Workbook

Sheet Home
B2: Food Delivery Analytics – Dashboard Hub
B3: 1,200 orders · 350 customers · 12 restaurants · 12 cities · 1-Jan-2025 to 4-Feb-2026. Every number is a live formula on the Data sheet.
B5: TOTAL ORDERS | D5: NET REVENUE | F5: DELIVERY SUCCESS | H5: CANCELLATION RATE | J5: AVG DELIVERY TIME | L5: AVG CUSTOMER RATING
B6: =COUNTA(d_ID) -> 1200 | D6: =SUMIFS(d_Net,d_Status,"Delivered") -> 699950 | F6: =IFERROR(COUNTIFS(d_Status,"Delivered")/COUNTA(d_ID),0) -> 0.65916667 | H6: =IFERROR(COUNTIFS(d_Status,"Cancelled")/COUNTA(d_ID),0) -> 0.16833333 | J6: =IFERROR(AVERAGEIFS(d_Time,d_Status,"Delivered"),0) -> 41.530973 | L6: =AVERAGE(d_CRating) -> 4.0183333
B7: All statuses | D7: Delivered orders | F7: Delivered ÷ all | H7: Cancelled ÷ all | J7: Delivered orders | L7: Out of 5
B10: Dashboards (click to open)
B12: 1. Order Analytics | F12: Volume, status mix, cuisine, payment, city
B14: 2. Restaurant Performance | F14: Revenue, ratings, speed, cancel rate per restaurant
B16: 3. Customer Analytics | F16: Repeat rate, age, gender, top customers
B18: 4. Delivery Partner Analytics | F18: Delivery fleet by city & distance (no partner ID in data)
B20: 5. Delivery Time | F20: Time bands, SLA on-time %, city & distance
B22: 6. Cancellation Analysis | F22: Rates by city, restaurant, payment, cuisine
B24: 7. Rating & Review | F24: Rating distribution, by restaurant / cuisine / city
B26: 8. Revenue Dashboard | F26: Gross, discounts, net by month, city, cuisine
B28: 9. Explorer | F28: Pick any grouping + metric; chart rebuilds instantly
B31: Definitions & assumptions
B32: • Interactive: each dashboard has yellow dropdown filters (Year, City, Cuisine, Payment, Order type) in row 4 – every KPI, chart and table recalculates. Set to All to clear. Home KPIs are always unfiltered.
B33: • Net revenue / gross revenue / discounts count Delivered orders only; Pending and Cancelled orders are reported separately.
B34: • Delivery-time metrics use Delivered orders only. SLA target is an input on the Delivery Time sheet (assumed 45 min).
B35: • Cancel rate = Cancelled ÷ all orders in the group. Lost value = Gross_Amount of cancelled orders.
B36: • Delivery Partner Analytics: the source file has no partner/rider column, so Order_Type = Delivery is used as the fleet.
B37: • Rating & Review: the source has star ratings only (no review text). Restaurant_Rating varies per order, so averages are used.
B38: • Blue font = editable inputs (month starts, band limits, SLA). Formulas read named ranges d_* on Data rows 2–5000, so appended rows are picked up.
B39: • Customers helper sheet lists customer IDs; add new IDs there if new customers are appended. Feb-26 is a partial month.

Sheet Order Analytics
B2: Order Analytics
B3: Order volume, status mix, order type, cuisines, payment methods and city demand. Source: Data sheet (1,200 orders, 1-Jan-2025 to 4-Feb-2026). ▸ Use the yellow filters in row 4 – every KPI, chart and table updates. | L3: ← Back to Home
B4: Year: | C4: All | D4: City: | E4: All | F4: Cuisine: | G4: All | H4: Payment: | I4: All | J4: Order type: | K4: All | L4: ="Orders in view: "&TEXT(COUNTIFS(d_ID,"<>",d_Year,$P$4,d_City,$Q$4,d_Cuisine,$R$4,d_Pay,$S$4,d_Type,$T$4),"#,##0") -> Orders in view: 1,200 | P4: =IF(C4="All",">0",C4) -> >0 | Q4: =IF(E4="All","*",E4) -> * | R4: =IF(G4="All","*",G4) -> * | S4: =IF(I4="All","*",I4) -> * | T4: =IF(K4="All","*",K4) -> *
B5: TOTAL ORDERS | D5: DELIVERED | F5: PENDING | H5: CANCELLED | J5: AVG ORDER VALUE | L5: DELIVERY SHARE
B6: =COUNTIFS(d_ID,"<>",d_Year,$P$4,d_City,$Q$4,d_Cuisine,$R$4,d_Pay,$S$4,d_Type,$T$4) -> 1200 | D6: =COUNTIFS(d_Status,"Delivered",d_Year,$P$4,d_City,$Q$4,d_Cuisine,$R$4,d_Pay,$S$4,d_Type,$T$4) -> 791 | F6: =COUNTIFS(d_Status,"Pending",d_Year,$P$4,d_City,$Q$4,d_Cuisine,$R$4,d_Pay,$S$4,d_Type,$T$4) -> 207 | H6: =COUNTIFS(d_Status,"Cancelled",d_Year,$P$4,d_City,$Q$4,d_Cuisine,$R$4,d_Pay,$S$4,d_Type,$T$4) -> 202 | J6: =AVERAGEIFS(d_OV,d_ID,"<>",d_Year,$P$4,d_City,$Q$4,d_Cuisine,$R$4,d_Pay,$S$4,d_Type,$T$4) -> 931.2875 | L6: =IFERROR(COUNTIFS(d_Type,"Delivery",d_Year,$P$4,d_City,$Q$4,d_Cuisine,$R$4,d_Pay,$S$4,d_Type,$T$4)/COUNTIFS(d_ID,"<>",d_Year,$P$4,d_City,$Q$4,d_Cuisine,$R$4,d_Pay,$S$4,d_Type,$T$4),0) -> 0.73416667
B7: All statuses | D7: Completed orders | F7: Not yet completed | H7: Cancelled orders | J7: Food value, all orders | L7: Delivery vs pickup
B57: Supporting data (feeds the charts above)
B59: Monthly order trend
B60: Month | C60: Month start | D60: Orders | E60: Delivered | F60: Pending | G60: Cancelled | H60: Avg order value
B61: =TEXT(C61,"mmm-yy") -> Jan-25 | C61: 45658 | D61: =COUNTIFS(d_Date,">="&$C61,d_Date,"<"&EDATE($C61,1),d_Year,$P$4,d_City,$Q$4,d_Cuisine,$R$4,d_Pay,$S$4,d_Type,$T$4) -> 93 | E61: =COUNTIFS(d_Date,">="&$C61,d_Date,"<"&EDATE($C61,1),d_Status,"Delivered",d_Year,$P$4,d_City,$Q$4,d_Cuisine,$R$4,d_Pay,$S$4,d_Type,$T$4) -> 66 | F61: =COUNTIFS(d_Date,">="&$C61,d_Date,"<"&EDATE($C61,1),d_Status,"Pending",d_Year,$P$4,d_City,$Q$4,d_Cuisine,$R$4,d_Pay,$S$4,d_Type,$T$4) -> 12 | G61: =COUNTIFS(d_Date,">="&$C61,d_Date,"<"&EDATE($C61,1),d_Status,"Cancelled",d_Year,$P$4,d_City,$Q$4,d_Cuisine,$R$4,d_Pay,$S$4,d_Type,$T$4) -> 15 | H61: =IFERROR(AVERAGEIFS(d_OV,d_Date,">="&$C61,d_Date,"<"&EDATE($C61,1),d_Year,$P$4,d_City,$Q$4,d_Cuisine,$R$4,d_Pay,$S$4,d_Type,$T$4),0) -> 919.65591
B62: =TEXT(C62,"mmm-yy") -> Feb-25 | C62: 45689 | D62: =COUNTIFS(d_Date,">="&$C62,d_Date,"<"&EDATE($C62,1),d_Year,$P$4,d_City,$Q$4,d_Cuisine,$R$4,d_Pay,$S$4,d_Type,$T$4) -> 84 | E62: =COUNTIFS(d_Date,">="&$C62,d_Date,"<"&EDATE($C62,1),d_Status,"Delivered",d_Year,$P$4,d_City,$Q$4,d_Cuisine,$R$4,d_Pay,$S$4,d_Type,$T$4) -> 48 | F62: =COUNTIFS(d_Date,">="&$C62,d_Date,"<"&EDATE($C62,1),d_Status,"Pending",d_Year,$P$4,d_City,$Q$4,d_Cuisine,$R$4,d_Pay,$S$4,d_Type,$T$4) -> 21 | G62: =COUNTIFS(d_Date,">="&$C62,d_Date,"<"&EDATE($C62,1),d_Status,"Cancelled",d_Year,$P$4,d_City,$Q$4,d_Cuisine,$R$4,d_Pay,$S$4,d_Type,$T$4) -> 15 | H62: =IFERROR(AVERAGEIFS(d_OV,d_Date,">="&$C62,d_Date,"<"&EDATE($C62,1),d_Year,$P$4,d_City,$Q$4,d_Cuisine,$R$4,d_Pay,$S$4,d_Type,$T$4),0) -> 942.97619
B63: =TEXT(C63,"mmm-yy") -> Mar-25 | C63: 45717 | D63: =COUNTIFS(d_Date,">="&$C63,d_Date,"<"&EDATE($C63,1),d_Year,$P$4,d_City,$Q$4,d_Cuisine,$R$4,d_Pay,$S$4,d_Type,$T$4) -> 93 | E63: =COUNTIFS(d_Date,">="&$C63,d_Date,"<"&EDATE($C63,1),d_Status,"Delivered",d_Year,$P$4,d_City,$Q$4,d_Cuisine,$R$4,d_Pay,$S$4,d_Type,$T$4) -> 55 | F63: =COUNTIFS(d_Date,">="&$C63,d_Date,"<"&EDATE($C63,1),d_Status,"Pending",d_Year,$P$4,d_City,$Q$4,d_Cuisine,$R$4,d_Pay,$S$4,d_Type,$T$4) -> 19 | G63: =COUNTIFS(d_Date,">="&$C63,d_Date,"<"&EDATE($C63,1),d_Status,"Cancelled",d_Year,$P$4,d_City,$Q$4,d_Cuisine,$R$4,d_Pay,$S$4,d_Type,$T$4) -> 19 | H63: =IFERROR(AVERAGEIFS(d_OV,d_Date,">="&$C63,d_Date,"<"&EDATE($C63,1),d_Year,$P$4,d_City,$Q$4,d_Cuisine,$R$4,d_Pay,$S$4,d_Type,$T$4),0) -> 969.89247
B64: =TEXT(C64,"mmm-yy") -> Apr-25 | C64: 45748 | D64: =COUNTIFS(d_Date,">="&$C64,d_Date,"<"&EDATE($C64,1),d_Year,$P$4,d_City,$Q$4,d_Cuisine,$R$4,d_Pay,$S$4,d_Type,$T$4) -> 90 | E64: =COUNTIFS(d_Date,">="&$C64,d_Date,"<"&EDATE($C64,1),d_Status,"Delivered",d_Year,$P$4,d_City,$Q$4,d_Cuisine,$R$4,d_Pay,$S$4,d_Type,$T$4) -> 61 | F64: =COUNTIFS(d_Date,">="&$C64,d_Date,"<"&EDATE($C64,1),d_Status,"Pending",d_Year,$P$4,d_City,$Q$4,d_Cuisine,$R$4,d_Pay,$S$4,d_Type,$T$4) -> 12 | G64: =COUNTIFS(d_Date,">="&$C64,d_Date,"<"&EDATE($C64,1),d_Status,"Cancelled",d_Year,$P$4,d_City,$Q$4,d_Cuisine,$R$4,d_Pay,$S$4,d_Type,$T$4) -> 17 | H64: =IFERROR(AVERAGEIFS(d_OV,d_Date,">="&$C64,d_Date,"<"&EDATE($C64,1),d_Year,$P$4,d_City,$Q$4,d_Cuisine,$R$4,d_Pay,$S$4,d_Type,$T$4),0) -> 883.05556
B65: =TEXT(C65,"mmm-yy") -> May-25 | C65: 45778 | D65: =COUNTIFS(d_Date,">="&$C65,d_Date,"<"&EDATE($C65,1),d_Year,$P$4,d_City,$Q$4,d_Cuisine,$R$4,d_Pay,$S$4,d_Type,$T$4) -> 93 | E65: =COUNTIFS(d_Date,">="&$C65,d_Date,"<"&EDATE($C65,1),d_Status,"Delivered",d_Year,$P$4,d_City,$Q$4,d_Cuisine,$R$4,d_Pay,$S$4,d_Type,$T$4) -> 59 | F65: =COUNTIFS(d_Date,">="&$C65,d_Date,"<"&EDATE($C65,1),d_Status,"Pending",d_Year,$P$4,d_City,$Q$4,d_Cuisine,$R$4,d_Pay,$S$4,d_Type,$T$4) -> 18 | G65: =COUNTIFS(d_Date,">="&$C65,d_Date,"<"&EDATE($C65,1),d_Status,"Cancelled",d_Year,$P$4,d_City,$Q$4,d_Cuisine,$R$4,d_Pay,$S$4,d_Type,$T$4) -> 16 | H65: =IFERROR(AVERAGEIFS(d_OV,d_Date,">="&$C65,d_Date,"<"&EDATE($C65,1),d_Year,$P$4,d_City,$Q$4,d_Cuisine,$R$4,d_Pay,$S$4,d_Type,$T$4),0) -> 921.97849
B66: =TEXT(C66,"mmm-yy") -> Jun-25 | C66: 45809 | D66: =COUNTIFS(d_Date,">="&$C66,d_Date,"<"&EDATE($C66,1),d_Year,$P$4,d_City,$Q$4,d_Cuisine,$R$4,d_Pay,$S$4,d_Type,$T$4) -> 90 | E66: =COUNTIFS(d_Date,">="&$C66,d_Date,"<"&EDATE($C66,1),d_Status,"Delivered",d_Year,$P$4,d_City,$Q$4,d_Cuisine,$R$4,d_Pay,$S$4,d_Type,$T$4) -> 58 | F66: =COUNTIFS(d_Date,">="&$C66,d_Date,"<"&EDATE($C66,1),d_Status,"Pending",d_Year,$P$4,d_City,$Q$4,d_Cuisine,$R$4,d_Pay,$S$4,d_Type,$T$4) -> 13 | G66: =COUNTIFS(d_Date,">="&$C66,d_Date,"<"&EDATE($C66,1),d_Status,"Cancelled",d_Year,$P$4,d_City,$Q$4,d_Cuisine,$R$4,d_Pay,$S$4,d_Type,$T$4) -> 19 | H66: =IFERROR(AVERAGEIFS(d_OV,d_Date,">="&$C66,d_Date,"<"&EDATE($C66,1),d_Year,$P$4,d_City,$Q$4,d_Cuisine,$R$4,d_Pay,$S$4,d_Type,$T$4),0) -> 997.96667
B67: =TEXT(C67,"mmm-yy") -> Jul-25 | C67: 45839 | D67: =COUNTIFS(d_Date,">="&$C67,d_Date,"<"&EDATE($C67,1),d_Year,$P$4,d_City,$Q$4,d_Cuisine,$R$4,d_Pay,$S$4,d_Type,$T$4) -> 93 | E67: =COUNTIFS(d_Date,">="&$C67,d_Date,"<"&EDATE($C67,1),d_Status,"Delivered",d_Year,$P$4,d_City,$Q$4,d_Cuisine,$R$4,d_Pay,$S$4,d_Type,$T$4) -> 59 | F67: =COUNTIFS(d_Date,">="&$C67,d_Date,"<"&EDATE($C67,1),d_Status,"Pending",d_Year,$P$4,d_City,$Q$4,d_Cuisine,$R$4,d_Pay,$S$4,d_Type,$T$4) -> 18 | G67: =COUNTIFS(d_Date,">="&$C67,d_Date,"<"&EDATE($C67,1),d_Status,"Cancelled",d_Year,$P$4,d_City,$Q$4,d_Cuisine,$R$4,d_Pay,$S$4,d_Type,$T$4) -> 16 | H67: =IFERROR(AVERAGEIFS(d_OV,d_Date,">="&$C67,d_Date,"<"&EDATE($C67,1),d_Year,$P$4,d_City,$Q$4,d_Cuisine,$R$4,d_Pay,$S$4,d_Type,$T$4),0) -> 989.21505
B68: =TEXT(C68,"mmm-yy") -> Aug-25 | C68: 45870 | D68: =COUNTIFS(d_Date,">="&$C68,d_Date,"<"&EDATE($C68,1),d_Year,$P$4,d_City,$Q$4,d_Cuisine,$R$4,d_Pay,$S$4,d_Type,$T$4) -> 93 | E68: =COUNTIFS(d_Date,">="&$C68,d_Date,"<"&EDATE($C68,1),d_Status,"Delivered",d_Year,$P$4,d_City,$Q$4,d_Cuisine,$R$4,d_Pay,$S$4,d_Type,$T$4) -> 70 | F68: =COUNTIFS(d_Date,">="&$C68,d_Date,"<"&EDATE($C68,1),d_Status,"Pending",d_Year,$P$4,d_City,$Q$4,d_Cuisine,$R$4,d_Pay,$S$4,d_Type,$T$4) -> 11 | G68: =COUNTIFS(d_Date,">="&$C68,d_Date,"<"&EDATE($C68,1),d_Status,"Cancelled",d_Year,$P$4,d_City,$Q$4,d_Cuisine,$R$4,d_Pay,$S$4,d_Type,$T$4) -> 12 | H68: =IFERROR(AVERAGEIFS(d_OV,d_Date,">="&$C68,d_Date,"<"&EDATE($C68,1),d_Year,$P$4,d_City,$Q$4,d_Cuisine,$R$4,d_Pay,$S$4,d_Type,$T$4),0) -> 876.88172
B69: =TEXT(C69,"mmm-yy") -> Sep-25 | C69: 45901 | D69: =COUNTIFS(d_Date,">="&$C69,d_Date,"<"&EDATE($C69,1),d_Year,$P$4,d_City,$Q$4,d_Cuisine,$R$4,d_Pay,$S$4,d_Type,$T$4) -> 90 | E69: =COUNTIFS(d_Date,">="&$C69,d_Date,"<"&EDATE($C69,1),d_Status,"Delivered",d_Year,$P$4,d_City,$Q$4,d_Cuisine,$R$4,d_Pay,$S$4,d_Type,$T$4) -> 60 | F69: =COUNTIFS(d_Date,">="&$C69,d_Date,"<"&EDATE($C69,1),d_Status,"Pending",d_Year,$P$4,d_City,$Q$4,d_Cuisine,$R$4,d_Pay,$S$4,d_Type,$T$4) -> 14 | G69: =COUNTIFS(d_Date,">="&$C69,d_Date,"<"&EDATE($C69,1),d_Status,"Cancelled",d_Year,$P$4,d_City,$Q$4,d_Cuisine,$R$4,d_Pay,$S$4,d_Type,$T$4) -> 16 | H69: =IFERROR(AVERAGEIFS(d_OV,d_Date,">="&$C69,d_Date,"<"&EDATE($C69,1),d_Year,$P$4,d_City,$Q$4,d_Cuisine,$R$4,d_Pay,$S$4,d_Type,$T$4),0) -> 910.43333
B70: =TEXT(C70,"mmm-yy") -> Oct-25 | C70: 45931 | D70: =COUNTIFS(d_Date,">="&$C70,d_Date,"<"&EDATE($C70,1),d_Year,$P$4,d_City,$Q$4,d_Cuisine,$R$4,d_Pay,$S$4,d_Type,$T$4) -> 93 | E70: =COUNTIFS(d_Date,">="&$C70,d_Date,"<"&EDATE($C70,1),d_Status,"Delivered",d_Year,$P$4,d_City,$Q$4,d_Cuisine,$R$4,d_Pay,$S$4,d_Type,$T$4) -> 63 | F70: =COUNTIFS(d_Date,">="&$C70,d_Date,"<"&EDATE($C70,1),d_Status,"Pending",d_Year,$P$4,d_City,$Q$4,d_Cuisine,$R$4,d_Pay,$S$4,d_Type,$T$4) -> 15 | G70: =COUNTIFS(d_Date,">="&$C70,d_Date,"<"&EDATE($C70,1),d_Status,"Cancelled",d_Year,$P$4,d_City,$Q$4,d_Cuisine,$R$4,d_Pay,$S$4,d_Type,$T$4) -> 15 | H70: =IFERROR(AVERAGEIFS(d_OV,d_Date,">="&$C70,d_Date,"<"&EDATE($C70,1),d_Year,$P$4,d_City,$Q$4,d_Cuisine,$R$4,d_Pay,$S$4,d_Type,$T$4),0) -> 937.03226
B71: =TEXT(C71,"mmm-yy") -> Nov-25 | C71: 45962 | D71: =COUNTIFS(d_Date,">="&$C71,d_Date,"<"&EDATE($C71,1),d_Year,$P$4,d_City,$Q$4,d_Cuisine,$R$4,d_Pay,$S$4,d_Type,$T$4) -> 90 | E71: =COUNTIFS(d_Date,">="&$C71,d_Date,"<"&EDATE($C71,1),d_Status,"Delivered",d_Year,$P$4,d_City,$Q$4,d_Cuisine,$R$4,d_Pay,$S$4,d_Type,$T$4) -> 61 | F71: =COUNTIFS(d_Date,">="&$C71,d_Date,"<"&EDATE($C71,1),d_Status,"Pending",d_Year,$P$4,d_City,$Q$4,d_Cuisine,$R$4,d_Pay,$S$4,d_Type,$T$4) -> 14 | G71: =COUNTIFS(d_Date,">="&$C71,d_Date,"<"&EDATE($C71,1),d_Status,"Cancelled",d_Year,$P$4,d_City,$Q$4,d_Cuisine,$R$4,d_Pay,$S$4,d_Type,$T$4) -> 15 | H71: =IFERROR(AVERAGEIFS(d_OV,d_Date,">="&$C71,d_Date,"<"&EDATE($C71,1),d_Year,$P$4,d_City,$Q$4,d_Cuisine,$R$4,d_Pay,$S$4,d_Type,$T$4),0) -> 951.56667
B72: =TEXT(C72,"mmm-yy") -> Dec-25 | C72: 45992 | D72: =COUNTIFS(d_Date,">="&$C72,d_Date,"<"&EDATE($C72,1),d_Year,$P$4,d_City,$Q$4,d_Cuisine,$R$4,d_Pay,$S$4,d_Type,$T$4) -> 93 | E72: =COUNTIFS(d_Date,">="&$C72,d_Date,"<"&EDATE($C72,1),d_Status,"Delivered",d_Year,$P$4,d_City,$Q$4,d_Cuisine,$R$4,d_Pay,$S$4,d_Type,$T$4) -> 61 | F72: =COUNTIFS(d_Date,">="&$C72,d_Date,"<"&EDATE($C72,1),d_Status,"Pending",d_Year,$P$4,d_City,$Q$4,d_Cuisine,$R$4,d_Pay,$S$4,d_Type,$T$4) -> 16 | G72: =COUNTIFS(d_Date,">="&$C72,d_Date,"<"&EDATE($C72,1),d_Status,"Cancelled",d_Year,$P$4,d_City,$Q$4,d_Cuisine,$R$4,d_Pay,$S$4,d_Type,$T$4) -> 16 | H72: =IFERROR(AVERAGEIFS(d_OV,d_Date,">="&$C72,d_Date,"<"&EDATE($C72,1),d_Year,$P$4,d_City,$Q$4,d_Cuisine,$R$4,d_Pay,$S$4,d_Type,$T$4),0) -> 946.56989
... B74: =TEXT(C74,"mmm-yy") -> Feb-26 | C74: 46054 | D74: =COUNTIFS(d_Date,">="&$C74,d_Date,"<"&EDATE($C74,1),d_Year,$P$4,d_City,$Q$4,d_Cuisine,$R$4,d_Pay,$S$4,d_Type,$T$4) -> 12 | E74: =COUNTIFS(d_Date,">="&$C74,d_Date,"<"&EDATE($C74,1),d_Status,"Delivered",d_Year,$P$4,d_City,$Q$4,d_Cuisine,$R$4,d_Pay,$S$4,d_Type,$T$4) -> 7 | F74: =COUNTIFS(d_Date,">="&$C74,d_Date,"<"&EDATE($C74,1),d_Status,"Pending",d_Year,$P$4,d_City,$Q$4,d_Cuisine,$R$4,d_Pay,$S$4,d_Type,$T$4) -> 4 | G74: =COUNTIFS(d_Date,">="&$C74,d_Date,"<"&EDATE($C74,1),d_Status,"Cancelled",d_Year,$P$4,d_City,$Q$4,d_Cuisine,$R$4,d_Pay,$S$4,d_Type,$T$4) -> 1 | H74: =IFERROR(AVERAGEIFS(d_OV,d_Date,">="&$C74,d_Date,"<"&EDATE($C74,1),d_Year,$P$4,d_City,$Q$4,d_Cuisine,$R$4,d_Pay,$S$4,d_Type,$T$4),0) -> 677.41667
B75: Total / Overall | D75: =SUM(D61:D74) -> 1200 | E75: =SUM(E61:E74) -> 791 | F75: =SUM(F61:F74) -> 207 | G75: =SUM(G61:G74) -> 202 | H75: =AVERAGEIFS(d_OV,d_ID,"<>",d_Year,$P$4,d_City,$Q$4,d_Cuisine,$R$4,d_Pay,$S$4,d_Type,$T$4) -> 931.2875
B76: Month start dates are inputs (blue). Feb-26 is a partial month (data ends 4-Feb-2026). Add rows if new months are appended.
B79: Order status mix
B80: Status | C80: Orders | D80: % of orders
B81: Delivered | C81: =COUNTIFS(d_Status,$B81,d_Year,$P$4,d_City,$Q$4,d_Cuisine,$R$4,d_Pay,$S$4,d_Type,$T$4) -> 791 | D81: =IFERROR(C81/COUNTIFS(d_ID,"<>",d_Year,$P$4,d_City,$Q$4,d_Cuisine,$R$4,d_Pay,$S$4,d_Type,$T$4),0) -> 0.65916667
B82: Pending | C82: =COUNTIFS(d_Status,$B82,d_Year,$P$4,d_City,$Q$4,d_Cuisine,$R$4,d_Pay,$S$4,d_Type,$T$4) -> 207 | D82: =IFERROR(C82/COUNTIFS(d_ID,"<>",d_Year,$P$4,d_City,$Q$4,d_Cuisine,$R$4,d_Pay,$S$4,d_Type,$T$4),0) -> 0.1725
B83: Cancelled | C83: =COUNTIFS(d_Status,$B83,d_Year,$P$4,d_City,$Q$4,d_Cuisine,$R$4,d_Pay,$S$4,d_Type,$T$4) -> 202 | D83: =IFERROR(C83/COUNTIFS(d_ID,"<>",d_Year,$P$4,d_City,$Q$4,d_Cuisine,$R$4,d_Pay,$S$4,d_Type,$T$4),0) -> 0.16833333
B84: Total / Overall | C84: =SUM(C81:C83) -> 1200 | D84: =SUM(D81:D83) -> 1
B87: Order type by status
B88: Order type | C88: Delivered | D88: Pending | E88: Cancelled | F88: Total
B89: Delivery | C89: =COUNTIFS(d_Type,$B89,d_Status,"Delivered",d_Year,$P$4,d_City,$Q$4,d_Cuisine,$R$4,d_Pay,$S$4,d_Type,$T$4) -> 592 | D89: =COUNTIFS(d_Type,$B89,d_Status,"Pending",d_Year,$P$4,d_City,$Q$4,d_Cuisine,$R$4,d_Pay,$S$4,d_Type,$T$4) -> 146 | E89: =COUNTIFS(d_Type,$B89,d_Status,"Cancelled",d_Year,$P$4,d_City,$Q$4,d_Cuisine,$R$4,d_Pay,$S$4,d_Type,$T$4) -> 143 | F89: =SUM(C89:E89) -> 881
B90: Pickup | C90: =COUNTIFS(d_Type,$B90,d_Status,"Delivered",d_Year,$P$4,d_City,$Q$4,d_Cuisine,$R$4,d_Pay,$S$4,d_Type,$T$4) -> 199 | D90: =COUNTIFS(d_Type,$B90,d_Status,"Pending",d_Year,$P$4,d_City,$Q$4,d_Cuisine,$R$4,d_Pay,$S$4,d_Type,$T$4) -> 61 | E90: =COUNTIFS(d_Type,$B90,d_Status,"Cancelled",d_Year,$P$4,d_City,$Q$4,d_Cuisine,$R$4,d_Pay,$S$4,d_Type,$T$4) -> 59 | F90: =SUM(C90:E90) -> 319
B91: Total / Overall | C91: =SUM(C89:C90) -> 791 | D91: =SUM(D89:D90) -> 207 | E91: =SUM(E89:E90) -> 202 | F91: =SUM(F89:F90) -> 1200
B94: Orders by cuisine
B95: Cuisine | C95: Orders | D95: Avg order value
B96: Burgers | C96: =COUNTIFS(d_Cuisine,$B96,d_Year,$P$4,d_City,$Q$4,d_Cuisine,$R$4,d_Pay,$S$4,d_Type,$T$4) -> 138 | D96: =IFERROR(AVERAGEIFS(d_OV,d_Cuisine,$B96,d_Year,$P$4,d_City,$Q$4,d_Cuisine,$R$4,d_Pay,$S$4,d_Type,$T$4),0) -> 919.62319
B97: North Indian | C97: =COUNTIFS(d_Cuisine,$B97,d_Year,$P$4,d_City,$Q$4,d_Cuisine,$R$4,d_Pay,$S$4,d_Type,$T$4) -> 136 | D97: =IFERROR(AVERAGEIFS(d_OV,d_Cuisine,$B97,d_Year,$P$4,d_City,$Q$4,d_Cuisine,$R$4,d_Pay,$S$4,d_Type,$T$4),0) -> 863.52206
B98: Desserts | C98: =COUNTIFS(d_Cuisine,$B98,d_Year,$P$4,d_City,$Q$4,d_Cuisine,$R$4,d_Pay,$S$4,d_Type,$T$4) -> 128 | D98: =IFERROR(AVERAGEIFS(d_OV,d_Cuisine,$B98,d_Year,$P$4,d_City,$Q$4,d_Cuisine,$R$4,d_Pay,$S$4,d_Type,$T$4),0) -> 914.59375
...

Sheet Restaurant Performance
B2: Restaurant Performance
B3: Orders, revenue, ratings, speed and cancellations for each restaurant. Revenue = Net_Amount of Delivered orders. ▸ Use the yellow filters in row 4 – every KPI, chart and table updates. | L3: ← Back to Home
B4: Year: | C4: All | D4: City: | E4: All | F4: Cuisine: | G4: All | H4: Payment: | I4: All | J4: Order type: | K4: All | L4: ="Orders in view: "&TEXT(COUNTIFS(d_ID,"<>",d_Year,$P$4,d_City,$Q$4,d_Cuisine,$R$4,d_Pay,$S$4,d_Type,$T$4),"#,##0") -> Orders in view: 1,200 | P4: =IF(C4="All",">0",C4) -> >0 | Q4: =IF(E4="All","*",E4) -> * | R4: =IF(G4="All","*",G4) -> * | S4: =IF(I4="All","*",I4) -> * | T4: =IF(K4="All","*",K4) -> *
B5: RESTAURANTS | D5: NET REVENUE | F5: TOP REVENUE RESTAURANT | H5: BEST RATED (CUSTOMERS) | J5: AVG RESTAURANT RATING | L5: HIGHEST CANCEL RATE
B6: =COUNTA(B61:B72) -> 12 | D6: =SUM(G61:G72) -> 699950 | F6: =INDEX(B61:B72,MATCH(MAX(G61:G72),G61:G72,0)) -> Burger House | H6: =INDEX(B61:B72,MATCH(MAX(J61:J72),J61:J72,0)) -> Cafe Aroma | J6: =AVERAGEIFS(d_RRating,d_ID,"<>",d_Year,$P$4,d_City,$Q$4,d_Cuisine,$R$4,d_Pay,$S$4,d_Type,$T$4) -> 3.7175 | L6: =INDEX(B61:B72,MATCH(MAX(F61:F72),F61:F72,0)) -> Food Street
B7: In the data | D7: Delivered orders | F7: Highest net revenue | H7: Highest avg customer rating | J7: Out of 5 | L7: Restaurant to watch
B57: Supporting data (feeds the charts above)
B59: Restaurant scorecard
B60: Restaurant | C60: Orders | D60: Delivered | E60: Cancelled | F60: Cancel rate | G60: Net revenue | H60: Avg order value | I60: Avg restaurant rating | J60: Avg customer rating | K60: Avg delivery time (min) | L60: Revenue rank
B61: Urban Tadka | C61: =COUNTIFS(d_Rest,$B61,d_Year,$P$4,d_City,$Q$4,d_Cuisine,$R$4,d_Pay,$S$4,d_Type,$T$4) -> 117 | D61: =COUNTIFS(d_Rest,$B61,d_Status,"Delivered",d_Year,$P$4,d_City,$Q$4,d_Cuisine,$R$4,d_Pay,$S$4,d_Type,$T$4) -> 78 | E61: =COUNTIFS(d_Rest,$B61,d_Status,"Cancelled",d_Year,$P$4,d_City,$Q$4,d_Cuisine,$R$4,d_Pay,$S$4,d_Type,$T$4) -> 16 | F61: =IFERROR(E61/C61,0) -> 0.13675214 | G61: =SUMIFS(d_Net,d_Rest,$B61,d_Status,"Delivered",d_Year,$P$4,d_City,$Q$4,d_Cuisine,$R$4,d_Pay,$S$4,d_Type,$T$4) -> 66822 | H61: =IFERROR(AVERAGEIFS(d_OV,d_Rest,$B61,d_Year,$P$4,d_City,$Q$4,d_Cuisine,$R$4,d_Pay,$S$4,d_Type,$T$4),0) -> 904.83761 | I61: =IFERROR(AVERAGEIFS(d_RRating,d_Rest,$B61,d_Year,$P$4,d_City,$Q$4,d_Cuisine,$R$4,d_Pay,$S$4,d_Type,$T$4),0) -> 3.7042735 | J61: =IFERROR(AVERAGEIFS(d_CRating,d_Rest,$B61,d_Year,$P$4,d_City,$Q$4,d_Cuisine,$R$4,d_Pay,$S$4,d_Type,$T$4),0) -> 4.0854701 | K61: =IFERROR(AVERAGEIFS(d_Time,d_Rest,$B61,d_Status,"Delivered",d_Year,$P$4,d_City,$Q$4,d_Cuisine,$R$4,d_Pay,$S$4,d_Type,$T$4),0) -> 41.089744 | L61: =RANK(G61,$G$61:$G$72) -> 2
B62: Taste Junction | C62: =COUNTIFS(d_Rest,$B62,d_Year,$P$4,d_City,$Q$4,d_Cuisine,$R$4,d_Pay,$S$4,d_Type,$T$4) -> 107 | D62: =COUNTIFS(d_Rest,$B62,d_Status,"Delivered",d_Year,$P$4,d_City,$Q$4,d_Cuisine,$R$4,d_Pay,$S$4,d_Type,$T$4) -> 73 | E62: =COUNTIFS(d_Rest,$B62,d_Status,"Cancelled",d_Year,$P$4,d_City,$Q$4,d_Cuisine,$R$4,d_Pay,$S$4,d_Type,$T$4) -> 15 | F62: =IFERROR(E62/C62,0) -> 0.14018692 | G62: =SUMIFS(d_Net,d_Rest,$B62,d_Status,"Delivered",d_Year,$P$4,d_City,$Q$4,d_Cuisine,$R$4,d_Pay,$S$4,d_Type,$T$4) -> 60113 | H62: =IFERROR(AVERAGEIFS(d_OV,d_Rest,$B62,d_Year,$P$4,d_City,$Q$4,d_Cuisine,$R$4,d_Pay,$S$4,d_Type,$T$4),0) -> 867.94393 | I62: =IFERROR(AVERAGEIFS(d_RRating,d_Rest,$B62,d_Year,$P$4,d_City,$Q$4,d_Cuisine,$R$4,d_Pay,$S$4,d_Type,$T$4),0) -> 3.7626168 | J62: =IFERROR(AVERAGEIFS(d_CRating,d_Rest,$B62,d_Year,$P$4,d_City,$Q$4,d_Cuisine,$R$4,d_Pay,$S$4,d_Type,$T$4),0) -> 3.9065421 | K62: =IFERROR(AVERAGEIFS(d_Time,d_Rest,$B62,d_Status,"Delivered",d_Year,$P$4,d_City,$Q$4,d_Cuisine,$R$4,d_Pay,$S$4,d_Type,$T$4),0) -> 42.027397 | L62: =RANK(G62,$G$61:$G$72) -> 5
B63: Cafe Aroma | C63: =COUNTIFS(d_Rest,$B63,d_Year,$P$4,d_City,$Q$4,d_Cuisine,$R$4,d_Pay,$S$4,d_Type,$T$4) -> 104 | D63: =COUNTIFS(d_Rest,$B63,d_Status,"Delivered",d_Year,$P$4,d_City,$Q$4,d_Cuisine,$R$4,d_Pay,$S$4,d_Type,$T$4) -> 70 | E63: =COUNTIFS(d_Rest,$B63,d_Status,"Cancelled",d_Year,$P$4,d_City,$Q$4,d_Cuisine,$R$4,d_Pay,$S$4,d_Type,$T$4) -> 22 | F63: =IFERROR(E63/C63,0) -> 0.21153846 | G63: =SUMIFS(d_Net,d_Rest,$B63,d_Status,"Delivered",d_Year,$P$4,d_City,$Q$4,d_Cuisine,$R$4,d_Pay,$S$4,d_Type,$T$4) -> 55539 | H63: =IFERROR(AVERAGEIFS(d_OV,d_Rest,$B63,d_Year,$P$4,d_City,$Q$4,d_Cuisine,$R$4,d_Pay,$S$4,d_Type,$T$4),0) -> 883.95192 | I63: =IFERROR(AVERAGEIFS(d_RRating,d_Rest,$B63,d_Year,$P$4,d_City,$Q$4,d_Cuisine,$R$4,d_Pay,$S$4,d_Type,$T$4),0) -> 3.7586538 | J63: =IFERROR(AVERAGEIFS(d_CRating,d_Rest,$B63,d_Year,$P$4,d_City,$Q$4,d_Cuisine,$R$4,d_Pay,$S$4,d_Type,$T$4),0) -> 4.2403846 | K63: =IFERROR(AVERAGEIFS(d_Time,d_Rest,$B63,d_Status,"Delivered",d_Year,$P$4,d_City,$Q$4,d_Cuisine,$R$4,d_Pay,$S$4,d_Type,$T$4),0) -> 42.228571 | L63: =RANK(G63,$G$61:$G$72) -> 9
B64: Delhi Zaika | C64: =COUNTIFS(d_Rest,$B64,d_Year,$P$4,d_City,$Q$4,d_Cuisine,$R$4,d_Pay,$S$4,d_Type,$T$4) -> 102 | D64: =COUNTIFS(d_Rest,$B64,d_Status,"Delivered",d_Year,$P$4,d_City,$Q$4,d_Cuisine,$R$4,d_Pay,$S$4,d_Type,$T$4) -> 70 | E64: =COUNTIFS(d_Rest,$B64,d_Status,"Cancelled",d_Year,$P$4,d_City,$Q$4,d_Cuisine,$R$4,d_Pay,$S$4,d_Type,$T$4) -> 17 | F64: =IFERROR(E64/C64,0) -> 0.16666667 | G64: =SUMIFS(d_Net,d_Rest,$B64,d_Status,"Delivered",d_Year,$P$4,d_City,$Q$4,d_Cuisine,$R$4,d_Pay,$S$4,d_Type,$T$4) -> 59187 | H64: =IFERROR(AVERAGEIFS(d_OV,d_Rest,$B64,d_Year,$P$4,d_City,$Q$4,d_Cuisine,$R$4,d_Pay,$S$4,d_Type,$T$4),0) -> 926.42157 | I64: =IFERROR(AVERAGEIFS(d_RRating,d_Rest,$B64,d_Year,$P$4,d_City,$Q$4,d_Cuisine,$R$4,d_Pay,$S$4,d_Type,$T$4),0) -> 3.7617647 | J64: =IFERROR(AVERAGEIFS(d_CRating,d_Rest,$B64,d_Year,$P$4,d_City,$Q$4,d_Cuisine,$R$4,d_Pay,$S$4,d_Type,$T$4),0) -> 3.8333333 | K64: =IFERROR(AVERAGEIFS(d_Time,d_Rest,$B64,d_Status,"Delivered",d_Year,$P$4,d_City,$Q$4,d_Cuisine,$R$4,d_Pay,$S$4,d_Type,$T$4),0) -> 42.842857 | L64: =RANK(G64,$G$61:$G$72) -> 6
B65: Burger House | C65: =COUNTIFS(d_Rest,$B65,d_Year,$P$4,d_City,$Q$4,d_Cuisine,$R$4,d_Pay,$S$4,d_Type,$T$4) -> 101 | D65: =COUNTIFS(d_Rest,$B65,d_Status,"Delivered",d_Year,$P$4,d_City,$Q$4,d_Cuisine,$R$4,d_Pay,$S$4,d_Type,$T$4) -> 69 | E65: =COUNTIFS(d_Rest,$B65,d_Status,"Cancelled",d_Year,$P$4,d_City,$Q$4,d_Cuisine,$R$4,d_Pay,$S$4,d_Type,$T$4) -> 17 | F65: =IFERROR(E65/C65,0) -> 0.16831683 | G65: =SUMIFS(d_Net,d_Rest,$B65,d_Status,"Delivered",d_Year,$P$4,d_City,$Q$4,d_Cuisine,$R$4,d_Pay,$S$4,d_Type,$T$4) -> 67652 | H65: =IFERROR(AVERAGEIFS(d_OV,d_Rest,$B65,d_Year,$P$4,d_City,$Q$4,d_Cuisine,$R$4,d_Pay,$S$4,d_Type,$T$4),0) -> 1019.6931 | I65: =IFERROR(AVERAGEIFS(d_RRating,d_Rest,$B65,d_Year,$P$4,d_City,$Q$4,d_Cuisine,$R$4,d_Pay,$S$4,d_Type,$T$4),0) -> 3.6237624 | J65: =IFERROR(AVERAGEIFS(d_CRating,d_Rest,$B65,d_Year,$P$4,d_City,$Q$4,d_Cuisine,$R$4,d_Pay,$S$4,d_Type,$T$4),0) -> 3.9009901 | K65: =IFERROR(AVERAGEIFS(d_Time,d_Rest,$B65,d_Status,"Delivered",d_Year,$P$4,d_City,$Q$4,d_Cuisine,$R$4,d_Pay,$S$4,d_Type,$T$4),0) -> 41.202899 | L65: =RANK(G65,$G$61:$G$72) -> 1
B66: Spice Hub | C66: =COUNTIFS(d_Rest,$B66,d_Year,$P$4,d_City,$Q$4,d_Cuisine,$R$4,d_Pay,$S$4,d_Type,$T$4) -> 100 | D66: =COUNTIFS(d_Rest,$B66,d_Status,"Delivered",d_Year,$P$4,d_City,$Q$4,d_Cuisine,$R$4,d_Pay,$S$4,d_Type,$T$4) -> 67 | E66: =COUNTIFS(d_Rest,$B66,d_Status,"Cancelled",d_Year,$P$4,d_City,$Q$4,d_Cuisine,$R$4,d_Pay,$S$4,d_Type,$T$4) -> 11 | F66: =IFERROR(E66/C66,0) -> 0.11 | G66: =SUMIFS(d_Net,d_Rest,$B66,d_Status,"Delivered",d_Year,$P$4,d_City,$Q$4,d_Cuisine,$R$4,d_Pay,$S$4,d_Type,$T$4) -> 63464 | H66: =IFERROR(AVERAGEIFS(d_OV,d_Rest,$B66,d_Year,$P$4,d_City,$Q$4,d_Cuisine,$R$4,d_Pay,$S$4,d_Type,$T$4),0) -> 926.22 | I66: =IFERROR(AVERAGEIFS(d_RRating,d_Rest,$B66,d_Year,$P$4,d_City,$Q$4,d_Cuisine,$R$4,d_Pay,$S$4,d_Type,$T$4),0) -> 3.676 | J66: =IFERROR(AVERAGEIFS(d_CRating,d_Rest,$B66,d_Year,$P$4,d_City,$Q$4,d_Cuisine,$R$4,d_Pay,$S$4,d_Type,$T$4),0) -> 4 | K66: =IFERROR(AVERAGEIFS(d_Time,d_Rest,$B66,d_Status,"Delivered",d_Year,$P$4,d_City,$Q$4,d_Cuisine,$R$4,d_Pay,$S$4,d_Type,$T$4),0) -> 40.402985 | L66: =RANK(G66,$G$61:$G$72) -> 3
B67: Pizza Point | C67: =COUNTIFS(d_Rest,$B67,d_Year,$P$4,d_City,$Q$4,d_Cuisine,$R$4,d_Pay,$S$4,d_Type,$T$4) -> 99 | D67: =COUNTIFS(d_Rest,$B67,d_Status,"Delivered",d_Year,$P$4,d_City,$Q$4,d_Cuisine,$R$4,d_Pay,$S$4,d_Type,$T$4) -> 74 | E67: =COUNTIFS(d_Rest,$B67,d_Status,"Cancelled",d_Year,$P$4,d_City,$Q$4,d_Cuisine,$R$4,d_Pay,$S$4,d_Type,$T$4) -> 18 | F67: =IFERROR(E67/C67,0) -> 0.18181818 | G67: =SUMIFS(d_Net,d_Rest,$B67,d_Status,"Delivered",d_Year,$P$4,d_City,$Q$4,d_Cuisine,$R$4,d_Pay,$S$4,d_Type,$T$4) -> 60969 | H67: =IFERROR(AVERAGEIFS(d_OV,d_Rest,$B67,d_Year,$P$4,d_City,$Q$4,d_Cuisine,$R$4,d_Pay,$S$4,d_Type,$T$4),0) -> 876 | I67: =IFERROR(AVERAGEIFS(d_RRating,d_Rest,$B67,d_Year,$P$4,d_City,$Q$4,d_Cuisine,$R$4,d_Pay,$S$4,d_Type,$T$4),0) -> 3.8666667 | J67: =IFERROR(AVERAGEIFS(d_CRating,d_Rest,$B67,d_Year,$P$4,d_City,$Q$4,d_Cuisine,$R$4,d_Pay,$S$4,d_Type,$T$4),0) -> 4.1818182 | K67: =IFERROR(AVERAGEIFS(d_Time,d_Rest,$B67,d_Status,"Delivered",d_Year,$P$4,d_City,$Q$4,d_Cuisine,$R$4,d_Pay,$S$4,d_Type,$T$4),0) -> 42.054054 | L67: =RANK(G67,$G$61:$G$72) -> 4
B68: Green Bowl | C68: =COUNTIFS(d_Rest,$B68,d_Year,$P$4,d_City,$Q$4,d_Cuisine,$R$4,d_Pay,$S$4,d_Type,$T$4) -> 98 | D68: =COUNTIFS(d_Rest,$B68,d_Status,"Delivered",d_Year,$P$4,d_City,$Q$4,d_Cuisine,$R$4,d_Pay,$S$4,d_Type,$T$4) -> 60 | E68: =COUNTIFS(d_Rest,$B68,d_Status,"Cancelled",d_Year,$P$4,d_City,$Q$4,d_Cuisine,$R$4,d_Pay,$S$4,d_Type,$T$4) -> 14 | F68: =IFERROR(E68/C68,0) -> 0.14285714 | G68: =SUMIFS(d_Net,d_Rest,$B68,d_Status,"Delivered",d_Year,$P$4,d_City,$Q$4,d_Cuisine,$R$4,d_Pay,$S$4,d_Type,$T$4) -> 54523 | H68: =IFERROR(AVERAGEIFS(d_OV,d_Rest,$B68,d_Year,$P$4,d_City,$Q$4,d_Cuisine,$R$4,d_Pay,$S$4,d_Type,$T$4),0) -> 978.67347 | I68: =IFERROR(AVERAGEIFS(d_RRating,d_Rest,$B68,d_Year,$P$4,d_City,$Q$4,d_Cuisine,$R$4,d_Pay,$S$4,d_Type,$T$4),0) -> 3.7 | J68: =IFERROR(AVERAGEIFS(d_CRating,d_Rest,$B68,d_Year,$P$4,d_City,$Q$4,d_Cuisine,$R$4,d_Pay,$S$4,d_Type,$T$4),0) -> 4.1836735 | K68: =IFERROR(AVERAGEIFS(d_Time,d_Rest,$B68,d_Status,"Delivered",d_Year,$P$4,d_City,$Q$4,d_Cuisine,$R$4,d_Pay,$S$4,d_Type,$T$4),0) -> 43.5 | L68: =RANK(G68,$G$61:$G$72) -> 11
B69: The Food Corner | C69: =COUNTIFS(d_Rest,$B69,d_Year,$P$4,d_City,$Q$4,d_Cuisine,$R$4,d_Pay,$S$4,d_Type,$T$4) -> 97 | D69: =COUNTIFS(d_Rest,$B69,d_Status,"Delivered",d_Year,$P$4,d_City,$Q$4,d_Cuisine,$R$4,d_Pay,$S$4,d_Type,$T$4) -> 62 | E69: =COUNTIFS(d_Rest,$B69,d_Status,"Cancelled",d_Year,$P$4,d_City,$Q$4,d_Cuisine,$R$4,d_Pay,$S$4,d_Type,$T$4) -> 21 | F69: =IFERROR(E69/C69,0) -> 0.21649485 | G69: =SUMIFS(d_Net,d_Rest,$B69,d_Status,"Delivered",d_Year,$P$4,d_City,$Q$4,d_Cuisine,$R$4,d_Pay,$S$4,d_Type,$T$4) -> 56948 | H69: =IFERROR(AVERAGEIFS(d_OV,d_Rest,$B69,d_Year,$P$4,d_City,$Q$4,d_Cuisine,$R$4,d_Pay,$S$4,d_Type,$T$4),0) -> 957.08247 | I69: =IFERROR(AVERAGEIFS(d_RRating,d_Rest,$B69,d_Year,$P$4,d_City,$Q$4,d_Cuisine,$R$4,d_Pay,$S$4,d_Type,$T$4),0) -> 3.7618557 | J69: =IFERROR(AVERAGEIFS(d_CRating,d_Rest,$B69,d_Year,$P$4,d_City,$Q$4,d_Cuisine,$R$4,d_Pay,$S$4,d_Type,$T$4),0) -> 3.8556701 | K69: =IFERROR(AVERAGEIFS(d_Time,d_Rest,$B69,d_Status,"Delivered",d_Year,$P$4,d_City,$Q$4,d_Cuisine,$R$4,d_Pay,$S$4,d_Type,$T$4),0) -> 41.548387 | L69: =RANK(G69,$G$61:$G$72) -> 8
B70: Royal Biryani | C70: =COUNTIFS(d_Rest,$B70,d_Year,$P$4,d_City,$Q$4,d_Cuisine,$R$4,d_Pay,$S$4,d_Type,$T$4) -> 93 | D70: =COUNTIFS(d_Rest,$B70,d_Status,"Delivered",d_Year,$P$4,d_City,$Q$4,d_Cuisine,$R$4,d_Pay,$S$4,d_Type,$T$4) -> 54 | E70: =COUNTIFS(d_Rest,$B70,d_Status,"Cancelled",d_Year,$P$4,d_City,$Q$4,d_Cuisine,$R$4,d_Pay,$S$4,d_Type,$T$4) -> 15 | F70: =IFERROR(E70/C70,0) -> 0.16129032 | G70: =SUMIFS(d_Net,d_Rest,$B70,d_Status,"Delivered",d_Year,$P$4,d_City,$Q$4,d_Cuisine,$R$4,d_Pay,$S$4,d_Type,$T$4) -> 42448 | H70: =IFERROR(AVERAGEIFS(d_OV,d_Rest,$B70,d_Year,$P$4,d_City,$Q$4,d_Cuisine,$R$4,d_Pay,$S$4,d_Type,$T$4),0) -> 863.54839 | I70: =IFERROR(AVERAGEIFS(d_RRating,d_Rest,$B70,d_Year,$P$4,d_City,$Q$4,d_Cuisine,$R$4,d_Pay,$S$4,d_Type,$T$4),0) -> 3.7215054 | J70: =IFERROR(AVERAGEIFS(d_CRating,d_Rest,$B70,d_Year,$P$4,d_City,$Q$4,d_Cuisine,$R$4,d_Pay,$S$4,d_Type,$T$4),0) -> 4.0215054 | K70: =IFERROR(AVERAGEIFS(d_Time,d_Rest,$B70,d_Status,"Delivered",d_Year,$P$4,d_City,$Q$4,d_Cuisine,$R$4,d_Pay,$S$4,d_Type,$T$4),0) -> 40.481481 | L70: =RANK(G70,$G$61:$G$72) -> 12
B71: Food Street | C71: =COUNTIFS(d_Rest,$B71,d_Year,$P$4,d_City,$Q$4,d_Cuisine,$R$4,d_Pay,$S$4,d_Type,$T$4) -> 93 | D71: =COUNTIFS(d_Rest,$B71,d_Status,"Delivered",d_Year,$P$4,d_City,$Q$4,d_Cuisine,$R$4,d_Pay,$S$4,d_Type,$T$4) -> 57 | E71: =COUNTIFS(d_Rest,$B71,d_Status,"Cancelled",d_Year,$P$4,d_City,$Q$4,d_Cuisine,$R$4,d_Pay,$S$4,d_Type,$T$4) -> 22 | F71: =IFERROR(E71/C71,0) -> 0.23655914 | G71: =SUMIFS(d_Net,d_Rest,$B71,d_Status,"Delivered",d_Year,$P$4,d_City,$Q$4,d_Cuisine,$R$4,d_Pay,$S$4,d_Type,$T$4) -> 54955 | H71: =IFERROR(AVERAGEIFS(d_OV,d_Rest,$B71,d_Year,$P$4,d_City,$Q$4,d_Cuisine,$R$4,d_Pay,$S$4,d_Type,$T$4),0) -> 989.1828 | I71: =IFERROR(AVERAGEIFS(d_RRating,d_Rest,$B71,d_Year,$P$4,d_City,$Q$4,d_Cuisine,$R$4,d_Pay,$S$4,d_Type,$T$4),0) -> 3.6021505 | J71: =IFERROR(AVERAGEIFS(d_CRating,d_Rest,$B71,d_Year,$P$4,d_City,$Q$4,d_Cuisine,$R$4,d_Pay,$S$4,d_Type,$T$4),0) -> 3.9677419 | K71: =IFERROR(AVERAGEIFS(d_Time,d_Rest,$B71,d_Status,"Delivered",d_Year,$P$4,d_City,$Q$4,d_Cuisine,$R$4,d_Pay,$S$4,d_Type,$T$4),0) -> 39.877193 | L71: =RANK(G71,$G$61:$G$72) -> 10
B72: Momo Nation | C72: =COUNTIFS(d_Rest,$B72,d_Year,$P$4,d_City,$Q$4,d_Cuisine,$R$4,d_Pay,$S$4,d_Type,$T$4) -> 89 | D72: =COUNTIFS(d_Rest,$B72,d_Status,"Delivered",d_Year,$P$4,d_City,$Q$4,d_Cuisine,$R$4,d_Pay,$S$4,d_Type,$T$4) -> 57 | E72: =COUNTIFS(d_Rest,$B72,d_Status,"Cancelled",d_Year,$P$4,d_City,$Q$4,d_Cuisine,$R$4,d_Pay,$S$4,d_Type,$T$4) -> 14 | F72: =IFERROR(E72/C72,0) -> 0.15730337 | G72: =SUMIFS(d_Net,d_Rest,$B72,d_Status,"Delivered",d_Year,$P$4,d_City,$Q$4,d_Cuisine,$R$4,d_Pay,$S$4,d_Type,$T$4) -> 57330 | H72: =IFERROR(AVERAGEIFS(d_OV,d_Rest,$B72,d_Year,$P$4,d_City,$Q$4,d_Cuisine,$R$4,d_Pay,$S$4,d_Type,$T$4),0) -> 999.96629 | I72: =IFERROR(AVERAGEIFS(d_RRating,d_Rest,$B72,d_Year,$P$4,d_City,$Q$4,d_Cuisine,$R$4,d_Pay,$S$4,d_Type,$T$4),0) -> 3.6561798 | J72: =IFERROR(AVERAGEIFS(d_CRating,d_Rest,$B72,d_Year,$P$4,d_City,$Q$4,d_Cuisine,$R$4,d_Pay,$S$4,d_Type,$T$4),0) -> 4.0337079 | K72: =IFERROR(AVERAGEIFS(d_Time,d_Rest,$B72,d_Status,"Delivered",d_Year,$P$4,d_City,$Q$4,d_Cuisine,$R$4,d_Pay,$S$4,d_Type,$T$4),0) -> 40.631579 | L72: =RANK(G72,$G$61:$G$72) -> 7
B73: Total / Overall | C73: =SUM(C61:C72) -> 1200 | D73: =SUM(D61:D72) -> 791 | E73: =SUM(E61:E72) -> 202 | F73: =IFERROR(E73/C73,0) -> 0.16833333 | G73: =SUM(G61:G72) -> 699950 | H73: =AVERAGEIFS(d_OV,d_ID,"<>",d_Year,$P$4,d_City,$Q$4,d_Cuisine,$R$4,d_Pay,$S$4,d_Type,$T$4) -> 931.2875 | I73: =AVERAGEIFS(d_RRating,d_ID,"<>",d_Year,$P$4,d_City,$Q$4,d_Cuisine,$R$4,d_Pay,$S$4,d_Type,$T$4) -> 3.7175 | J73: =AVERAGEIFS(d_CRating,d_ID,"<>",d_Year,$P$4,d_City,$Q$4,d_Cuisine,$R$4,d_Pay,$S$4,d_Type,$T$4) -> 4.0183333 | K73: =IFERROR(AVERAGEIFS(d_Time,d_Status,"Delivered",d_Year,$P$4,d_City,$Q$4,d_Cuisine,$R$4,d_Pay,$S$4,d_Type,$T$4),0) -> 41.530973

Sheet Customer Analytics
B2: Customer Analytics
B3: Who orders, how often and how much. Customer-level metrics come from the Customers helper sheet. ▸ Use the yellow filters in row 4 – every KPI, chart and table updates. | L3: ← Back to Home
B4: Year: | C4: All | D4: City: | E4: All | F4: Cuisine: | G4: All | H4: Payment: | I4: All | J4: Order type: | K4: All | L4: ="Orders in view: "&TEXT(COUNTIFS(d_ID,"<>",d_Year,$P$4,d_City,$Q$4,d_Cuisine,$R$4,d_Pay,$S$4,d_Type,$T$4),"#,##0") -> Orders in view: 1,200 | P4: =IF(C4="All",">0",C4) -> >0 | Q4: =IF(E4="All","*",E4) -> * | R4: =IF(G4="All","*",G4) -> * | S4: =IF(I4="All","*",I4) -> * | T4: =IF(K4="All","*",K4) -> *
B5: UNIQUE CUSTOMERS | D5: REPEAT CUSTOMERS | F5: REPEAT RATE | H5: ORDERS / CUSTOMER | J5: AVG CUSTOMER AGE | L5: AVG SPEND / CUSTOMER
B6: =COUNTIF(Customers!$B$2:$B$351,">0") -> 350 | D6: =COUNTIF(Customers!$B$2:$B$351,">1") -> 350 | F6: =IFERROR(COUNTIF(Customers!$B$2:$B$351,">1")/COUNTIF(Customers!$B$2:$B$351,">0"),0) -> 1 | H6: =IFERROR(COUNTIFS(d_ID,"<>",d_Year,$P$4,d_City,$Q$4,d_Cuisine,$R$4,d_Pay,$S$4,d_Type,$T$4)/COUNTIF(Customers!$B$2:$B$351,">0"),0) -> 3.4285714 | J6: =AVERAGEIFS(d_Age,d_ID,"<>",d_Year,$P$4,d_City,$Q$4,d_Cuisine,$R$4,d_Pay,$S$4,d_Type,$T$4) -> 39.025 | L6: =IFERROR(SUM(Customers!$D$2:$D$351)/COUNTIF(Customers!$B$2:$B$351,">0"),0) -> 1999.8571
B7: Distinct Customer_IDs | D7: Ordered 2+ times | F7: Repeat ÷ unique | H7: Average frequency | J7: Years | L7: Net spend, delivered
B57: Supporting data (feeds the charts above)
B59: Age-group analysis
B60: Age group | C60: Min age | D60: Max age | E60: Orders | F60: Delivered | G60: Net revenue | H60: Avg order value | I60: Avg rating given
B61: 18–24 | C61: 18 | D61: 24 | E61: =COUNTIFS(d_Age,">="&$C61,d_Age,"<="&$D61,d_Year,$P$4,d_City,$Q$4,d_Cuisine,$R$4,d_Pay,$S$4,d_Type,$T$4) -> 186 | F61: =COUNTIFS(d_Age,">="&$C61,d_Age,"<="&$D61,d_Status,"Delivered",d_Year,$P$4,d_City,$Q$4,d_Cuisine,$R$4,d_Pay,$S$4,d_Type,$T$4) -> 130 | G61: =SUMIFS(d_Net,d_Age,">="&$C61,d_Age,"<="&$D61,d_Status,"Delivered",d_Year,$P$4,d_City,$Q$4,d_Cuisine,$R$4,d_Pay,$S$4,d_Type,$T$4) -> 105420 | H61: =IFERROR(AVERAGEIFS(d_OV,d_Age,">="&$C61,d_Age,"<="&$D61,d_Year,$P$4,d_City,$Q$4,d_Cuisine,$R$4,d_Pay,$S$4,d_Type,$T$4),0) -> 856.63978 | I61: =IFERROR(AVERAGEIFS(d_CRating,d_Age,">="&$C61,d_Age,"<="&$D61,d_Year,$P$4,d_City,$Q$4,d_Cuisine,$R$4,d_Pay,$S$4,d_Type,$T$4),0) -> 4.0537634
B62: 25–34 | C62: 25 | D62: 34 | E62: =COUNTIFS(d_Age,">="&$C62,d_Age,"<="&$D62,d_Year,$P$4,d_City,$Q$4,d_Cuisine,$R$4,d_Pay,$S$4,d_Type,$T$4) -> 285 | F62: =COUNTIFS(d_Age,">="&$C62,d_Age,"<="&$D62,d_Status,"Delivered",d_Year,$P$4,d_City,$Q$4,d_Cuisine,$R$4,d_Pay,$S$4,d_Type,$T$4) -> 181 | G62: =SUMIFS(d_Net,d_Age,">="&$C62,d_Age,"<="&$D62,d_Status,"Delivered",d_Year,$P$4,d_City,$Q$4,d_Cuisine,$R$4,d_Pay,$S$4,d_Type,$T$4) -> 160352 | H62: =IFERROR(AVERAGEIFS(d_OV,d_Age,">="&$C62,d_Age,"<="&$D62,d_Year,$P$4,d_City,$Q$4,d_Cuisine,$R$4,d_Pay,$S$4,d_Type,$T$4),0) -> 947.44211 | I62: =IFERROR(AVERAGEIFS(d_CRating,d_Age,">="&$C62,d_Age,"<="&$D62,d_Year,$P$4,d_City,$Q$4,d_Cuisine,$R$4,d_Pay,$S$4,d_Type,$T$4),0) -> 3.9438596
B63: 35–44 | C63: 35 | D63: 44 | E63: =COUNTIFS(d_Age,">="&$C63,d_Age,"<="&$D63,d_Year,$P$4,d_City,$Q$4,d_Cuisine,$R$4,d_Pay,$S$4,d_Type,$T$4) -> 279 | F63: =COUNTIFS(d_Age,">="&$C63,d_Age,"<="&$D63,d_Status,"Delivered",d_Year,$P$4,d_City,$Q$4,d_Cuisine,$R$4,d_Pay,$S$4,d_Type,$T$4) -> 180 | G63: =SUMIFS(d_Net,d_Age,">="&$C63,d_Age,"<="&$D63,d_Status,"Delivered",d_Year,$P$4,d_City,$Q$4,d_Cuisine,$R$4,d_Pay,$S$4,d_Type,$T$4) -> 167235 | H63: =IFERROR(AVERAGEIFS(d_OV,d_Age,">="&$C63,d_Age,"<="&$D63,d_Year,$P$4,d_City,$Q$4,d_Cuisine,$R$4,d_Pay,$S$4,d_Type,$T$4),0) -> 983.70968 | I63: =IFERROR(AVERAGEIFS(d_CRating,d_Age,">="&$C63,d_Age,"<="&$D63,d_Year,$P$4,d_City,$Q$4,d_Cuisine,$R$4,d_Pay,$S$4,d_Type,$T$4),0) -> 3.9318996
B64: 45–54 | C64: 45 | D64: 54 | E64: =COUNTIFS(d_Age,">="&$C64,d_Age,"<="&$D64,d_Year,$P$4,d_City,$Q$4,d_Cuisine,$R$4,d_Pay,$S$4,d_Type,$T$4) -> 294 | F64: =COUNTIFS(d_Age,">="&$C64,d_Age,"<="&$D64,d_Status,"Delivered",d_Year,$P$4,d_City,$Q$4,d_Cuisine,$R$4,d_Pay,$S$4,d_Type,$T$4) -> 197 | G64: =SUMIFS(d_Net,d_Age,">="&$C64,d_Age,"<="&$D64,d_Status,"Delivered",d_Year,$P$4,d_City,$Q$4,d_Cuisine,$R$4,d_Pay,$S$4,d_Type,$T$4) -> 173287 | H64: =IFERROR(AVERAGEIFS(d_OV,d_Age,">="&$C64,d_Age,"<="&$D64,d_Year,$P$4,d_City,$Q$4,d_Cuisine,$R$4,d_Pay,$S$4,d_Type,$T$4),0) -> 902.56463 | I64: =IFERROR(AVERAGEIFS(d_CRating,d_Age,">="&$C64,d_Age,"<="&$D64,d_Year,$P$4,d_City,$Q$4,d_Cuisine,$R$4,d_Pay,$S$4,d_Type,$T$4),0) -> 4.0816327
B65: 55–60 | C65: 55 | D65: 60 | E65: =COUNTIFS(d_Age,">="&$C65,d_Age,"<="&$D65,d_Year,$P$4,d_City,$Q$4,d_Cuisine,$R$4,d_Pay,$S$4,d_Type,$T$4) -> 156 | F65: =COUNTIFS(d_Age,">="&$C65,d_Age,"<="&$D65,d_Status,"Delivered",d_Year,$P$4,d_City,$Q$4,d_Cuisine,$R$4,d_Pay,$S$4,d_Type,$T$4) -> 103 | G65: =SUMIFS(d_Net,d_Age,">="&$C65,d_Age,"<="&$D65,d_Status,"Delivered",d_Year,$P$4,d_City,$Q$4,d_Cuisine,$R$4,d_Pay,$S$4,d_Type,$T$4) -> 93656 | H65: =IFERROR(AVERAGEIFS(d_OV,d_Age,">="&$C65,d_Age,"<="&$D65,d_Year,$P$4,d_City,$Q$4,d_Cuisine,$R$4,d_Pay,$S$4,d_Type,$T$4),0) -> 951.15385 | I65: =IFERROR(AVERAGEIFS(d_CRating,d_Age,">="&$C65,d_Age,"<="&$D65,d_Year,$P$4,d_City,$Q$4,d_Cuisine,$R$4,d_Pay,$S$4,d_Type,$T$4),0) -> 4.1474359
B66: Total / Overall | E66: =SUM(E61:E65) -> 1200 | F66: =SUM(F61:F65) -> 791 | G66: =SUM(G61:G65) -> 699950 | H66: =AVERAGEIFS(d_OV,d_ID,"<>",d_Year,$P$4,d_City,$Q$4,d_Cuisine,$R$4,d_Pay,$S$4,d_Type,$T$4) -> 931.2875 | I66: =AVERAGEIFS(d_CRating,d_ID,"<>",d_Year,$P$4,d_City,$Q$4,d_Cuisine,$R$4,d_Pay,$S$4,d_Type,$T$4) -> 4.0183333
B67: Age bounds are inputs (blue) – edit to re-band.
B70: Gender split
B71: Gender | C71: Orders | D71: % of orders | E71: Avg order value
B72: Female | C72: =COUNTIFS(d_Gender,$B72,d_Year,$P$4,d_City,$Q$4,d_Cuisine,$R$4,d_Pay,$S$4,d_Type,$T$4) -> 589 | D72: =IFERROR(C72/COUNTIFS(d_ID,"<>",d_Year,$P$4,d_City,$Q$4,d_Cuisine,$R$4,d_Pay,$S$4,d_Type,$T$4),0) -> 0.49083333 | E72: =IFERROR(AVERAGEIFS(d_OV,d_Gender,$B72,d_Year,$P$4,d_City,$Q$4,d_Cuisine,$R$4,d_Pay,$S$4,d_Type,$T$4),0) -> 928.77759
B73: Male | C73: =COUNTIFS(d_Gender,$B73,d_Year,$P$4,d_City,$Q$4,d_Cuisine,$R$4,d_Pay,$S$4,d_Type,$T$4) -> 576 | D73: =IFERROR(C73/COUNTIFS(d_ID,"<>",d_Year,$P$4,d_City,$Q$4,d_Cuisine,$R$4,d_Pay,$S$4,d_Type,$T$4),0) -> 0.48 | E73: =IFERROR(AVERAGEIFS(d_OV,d_Gender,$B73,d_Year,$P$4,d_City,$Q$4,d_Cuisine,$R$4,d_Pay,$S$4,d_Type,$T$4),0) -> 929.30035
B74: Other | C74: =COUNTIFS(d_Gender,$B74,d_Year,$P$4,d_City,$Q$4,d_Cuisine,$R$4,d_Pay,$S$4,d_Type,$T$4) -> 35 | D74: =IFERROR(C74/COUNTIFS(d_ID,"<>",d_Year,$P$4,d_City,$Q$4,d_Cuisine,$R$4,d_Pay,$S$4,d_Type,$T$4),0) -> 0.029166667 | E74: =IFERROR(AVERAGEIFS(d_OV,d_Gender,$B74,d_Year,$P$4,d_City,$Q$4,d_Cuisine,$R$4,d_Pay,$S$4,d_Type,$T$4),0) -> 1006.2286
B75: Total / Overall | C75: =SUM(C72:C74) -> 1200 | D75: =SUM(D72:D74) -> 1 | E75: =AVERAGEIFS(d_OV,d_ID,"<>",d_Year,$P$4,d_City,$Q$4,d_Cuisine,$R$4,d_Pay,$S$4,d_Type,$T$4) -> 931.2875
B78: Order-frequency distribution
B79: Orders per customer | C79: Customers | D79: % of customers
B80: 1 order | C80: =COUNTIF(Customers!$B$2:$B$351,1) -> 0 | D80: =IFERROR(C80/COUNTIF(Customers!$B$2:$B$351,">0"),0) -> 0
B81: 2 orders | C81: =COUNTIF(Customers!$B$2:$B$351,2) -> 0 | D81: =IFERROR(C81/COUNTIF(Customers!$B$2:$B$351,">0"),0) -> 0
B82: 3 orders | C82: =COUNTIF(Customers!$B$2:$B$351,3) -> 200 | D82: =IFERROR(C82/COUNTIF(Customers!$B$2:$B$351,">0"),0) -> 0.57142857
B83: 4 orders | C83: =COUNTIF(Customers!$B$2:$B$351,4) -> 150 | D83: =IFERROR(C83/COUNTIF(Customers!$B$2:$B$351,">0"),0) -> 0.42857143
B84: 5 orders | C84: =COUNTIF(Customers!$B$2:$B$351,5) -> 0 | D84: =IFERROR(C84/COUNTIF(Customers!$B$2:$B$351,">0"),0) -> 0
B85: 6+ orders | C85: =COUNTIF(Customers!$B$2:$B$351,">=6") -> 0 | D85: =IFERROR(C85/COUNTIF(Customers!$B$2:$B$351,">0"),0) -> 0
B86: Total / Overall | C86: =SUM(C80:C85) -> 350 | D86: =SUM(D80:D85) -> 1
B89: Top 10 customers by net spend
B90: Rank | C90: Customer ID | D90: Orders | E90: Net spend | F90: Avg rating given
B91: 1 | C91: =INDEX(Customers!$A$2:$A$351,MATCH($B91,Customers!$G$2:$G$351,0)) -> C1052 | D91: =INDEX(Customers!$B$2:$B$351,MATCH($B91,Customers!$G$2:$G$351,0)) -> 4 | E91: =INDEX(Customers!$D$2:$D$351,MATCH($B91,Customers!$G$2:$G$351,0)) -> 5485 | F91: =INDEX(Customers!$E$2:$E$351,MATCH($B91,Customers!$G$2:$G$351,0)) -> 4.25
B92: 2 | C92: =INDEX(Customers!$A$2:$A$351,MATCH($B92,Customers!$G$2:$G$351,0)) -> C1075 | D92: =INDEX(Customers!$B$2:$B$351,MATCH($B92,Customers!$G$2:$G$351,0)) -> 4 | E92: =INDEX(Customers!$D$2:$D$351,MATCH($B92,Customers!$G$2:$G$351,0)) -> 4940 | F92: =INDEX(Customers!$E$2:$E$351,MATCH($B92,Customers!$G$2:$G$351,0)) -> 4.5
B93: 3 | C93: =INDEX(Customers!$A$2:$A$351,MATCH($B93,Customers!$G$2:$G$351,0)) -> C1235 | D93: =INDEX(Customers!$B$2:$B$351,MATCH($B93,Customers!$G$2:$G$351,0)) -> 3 | E93: =INDEX(Customers!$D$2:$D$351,MATCH($B93,Customers!$G$2:$G$351,0)) -> 4806 | F93: =INDEX(Customers!$E$2:$E$351,MATCH($B93,Customers!$G$2:$G$351,0)) -> 3.6666667
B94: 4 | C94: =INDEX(Customers!$A$2:$A$351,MATCH($B94,Customers!$G$2:$G$351,0)) -> C1025 | D94: =INDEX(Customers!$B$2:$B$351,MATCH($B94,Customers!$G$2:$G$351,0)) -> 4 | E94: =INDEX(Customers!$D$2:$D$351,MATCH($B94,Customers!$G$2:$G$351,0)) -> 4768 | F94: =INDEX(Customers!$E$2:$E$351,MATCH($B94,Customers!$G$2:$G$351,0)) -> 4
B95: 5 | C95: =INDEX(Customers!$A$2:$A$351,MATCH($B95,Customers!$G$2:$G$351,0)) -> C1053 | D95: =INDEX(Customers!$B$2:$B$351,MATCH($B95,Customers!$G$2:$G$351,0)) -> 4 | E95: =INDEX(Customers!$D$2:$D$351,MATCH($B95,Customers!$G$2:$G$351,0)) -> 4682 | F95: =INDEX(Customers!$E$2:$E$351,MATCH($B95,Customers!$G$2:$G$351,0)) -> 4.5
B96: 6 | C96: =INDEX(Customers!$A$2:$A$351,MATCH($B96,Customers!$G$2:$G$351,0)) -> C1126 | D96: =INDEX(Customers!$B$2:$B$351,MATCH($B96,Customers!$G$2:$G$351,0)) -> 4 | E96: =INDEX(Customers!$D$2:$D$351,MATCH($B96,Customers!$G$2:$G$351,0)) -> 4548 | F96: =INDEX(Customers!$E$2:$E$351,MATCH($B96,Customers!$G$2:$G$351,0)) -> 4.5
B97: 7 | C97: =INDEX(Customers!$A$2:$A$351,MATCH($B97,Customers!$G$2:$G$351,0)) -> C1111 | D97: =INDEX(Customers!$B$2:$B$351,MATCH($B97,Customers!$G$2:$G$351,0)) -> 4 | E97: =INDEX(Customers!$D$2:$D$351,MATCH($B97,Customers!$G$2:$G$351,0)) -> 4505 | F97: =INDEX(Customers!$E$2:$E$351,MATCH($B97,Customers!$G$2:$G$351,0)) -> 5
...

Sheet Delivery Partner Analytics
B2: Delivery Partner Analytics
B3: The data has no delivery-partner ID, so this view analyses the delivery fleet (Order_Type = Delivery) by city, distance and status. Add a Partner_ID column to unlock per-partner scorecards. ▸ Use the yellow filters in row 4 – every KPI, chart and table updates. | L3: ← Back to Home
B4: Year: | C4: All | D4: City: | E4: All | F4: Cuisine: | G4: All | H4: Payment: | I4: All | J4: Order type: | K4: All | L4: ="Orders in view: "&TEXT(COUNTIFS(d_ID,"<>",d_Year,$P$4,d_City,$Q$4,d_Cuisine,$R$4,d_Pay,$S$4,d_Type,$T$4),"#,##0") -> Orders in view: 1,200 | P4: =IF(C4="All",">0",C4) -> >0 | Q4: =IF(E4="All","*",E4) -> * | R4: =IF(G4="All","*",G4) -> * | S4: =IF(I4="All","*",I4) -> * | T4: =IF(K4="All","*",K4) -> *
B5: DELIVERY ORDERS | D5: DELIVERED | F5: SUCCESS RATE | H5: AVG DELIVERY TIME | J5: AVG DISTANCE | L5: DELIVERY FEES EARNED
B6: =COUNTIFS(d_Type,"Delivery",d_Year,$P$4,d_City,$Q$4,d_Cuisine,$R$4,d_Pay,$S$4,d_Type,$T$4) -> 881 | D6: =COUNTIFS(d_Type,"Delivery",d_Status,"Delivered",d_Year,$P$4,d_City,$Q$4,d_Cuisine,$R$4,d_Pay,$S$4,d_Type,$T$4) -> 592 | F6: =IFERROR(COUNTIFS(d_Type,"Delivery",d_Status,"Delivered",d_Year,$P$4,d_City,$Q$4,d_Cuisine,$R$4,d_Pay,$S$4,d_Type,$T$4)/COUNTIFS(d_Type,"Delivery",d_Year,$P$4,d_City,$Q$4,d_Cuisine,$R$4,d_Pay,$S$4,d_Type,$T$4),0) -> 0.67196368 | H6: =IFERROR(AVERAGEIFS(d_Time,d_Type,"Delivery",d_Status,"Delivered",d_Year,$P$4,d_City,$Q$4,d_Cuisine,$R$4,d_Pay,$S$4,d_Type,$T$4),0) -> 41.694257 | J6: =IFERROR(AVERAGEIFS(d_Dist,d_Type,"Delivery",d_Year,$P$4,d_City,$Q$4,d_Cuisine,$R$4,d_Pay,$S$4,d_Type,$T$4),0) -> 7.6994325 | L6: =SUMIFS(d_Fee,d_Type,"Delivery",d_Status,"Delivered",d_Year,$P$4,d_City,$Q$4,d_Cuisine,$R$4,d_Pay,$S$4,d_Type,$T$4) -> 18100
B7: Order_Type = Delivery | D7: Successfully delivered | F7: Delivered ÷ delivery orders | H7: Delivered deliveries | J7: All delivery orders | L7: Delivered deliveries
B57: Supporting data (feeds the charts above)
B59: Delivery fleet by city
B60: City | C60: Delivery orders | D60: Delivered | E60: Success rate | F60: Avg delivery time (min) | G60: Avg distance (km) | H60: Delivery fees earned
B61: Delhi | C61: =COUNTIFS(d_City,$B61,d_Type,"Delivery",d_Year,$P$4,d_City,$Q$4,d_Cuisine,$R$4,d_Pay,$S$4,d_Type,$T$4) -> 85 | D61: =COUNTIFS(d_City,$B61,d_Type,"Delivery",d_Status,"Delivered",d_Year,$P$4,d_City,$Q$4,d_Cuisine,$R$4,d_Pay,$S$4,d_Type,$T$4) -> 58 | E61: =IFERROR(D61/C61,0) -> 0.68235294 | F61: =IFERROR(AVERAGEIFS(d_Time,d_City,$B61,d_Type,"Delivery",d_Status,"Delivered",d_Year,$P$4,d_City,$Q$4,d_Cuisine,$R$4,d_Pay,$S$4,d_Type,$T$4),0) -> 40.068966 | G61: =IFERROR(AVERAGEIFS(d_Dist,d_City,$B61,d_Type,"Delivery",d_Year,$P$4,d_City,$Q$4,d_Cuisine,$R$4,d_Pay,$S$4,d_Type,$T$4),0) -> 7.3658824 | H61: =SUMIFS(d_Fee,d_City,$B61,d_Type,"Delivery",d_Status,"Delivered",d_Year,$P$4,d_City,$Q$4,d_Cuisine,$R$4,d_Pay,$S$4,d_Type,$T$4) -> 1500
B62: Ahmedabad | C62: =COUNTIFS(d_City,$B62,d_Type,"Delivery",d_Year,$P$4,d_City,$Q$4,d_Cuisine,$R$4,d_Pay,$S$4,d_Type,$T$4) -> 88 | D62: =COUNTIFS(d_City,$B62,d_Type,"Delivery",d_Status,"Delivered",d_Year,$P$4,d_City,$Q$4,d_Cuisine,$R$4,d_Pay,$S$4,d_Type,$T$4) -> 61 | E62: =IFERROR(D62/C62,0) -> 0.69318182 | F62: =IFERROR(AVERAGEIFS(d_Time,d_City,$B62,d_Type,"Delivery",d_Status,"Delivered",d_Year,$P$4,d_City,$Q$4,d_Cuisine,$R$4,d_Pay,$S$4,d_Type,$T$4),0) -> 42.393443 | G62: =IFERROR(AVERAGEIFS(d_Dist,d_City,$B62,d_Type,"Delivery",d_Year,$P$4,d_City,$Q$4,d_Cuisine,$R$4,d_Pay,$S$4,d_Type,$T$4),0) -> 7.6806818 | H62: =SUMIFS(d_Fee,d_City,$B62,d_Type,"Delivery",d_Status,"Delivered",d_Year,$P$4,d_City,$Q$4,d_Cuisine,$R$4,d_Pay,$S$4,d_Type,$T$4) -> 1620
B63: Bengaluru | C63: =COUNTIFS(d_City,$B63,d_Type,"Delivery",d_Year,$P$4,d_City,$Q$4,d_Cuisine,$R$4,d_Pay,$S$4,d_Type,$T$4) -> 78 | D63: =COUNTIFS(d_City,$B63,d_Type,"Delivery",d_Status,"Delivered",d_Year,$P$4,d_City,$Q$4,d_Cuisine,$R$4,d_Pay,$S$4,d_Type,$T$4) -> 54 | E63: =IFERROR(D63/C63,0) -> 0.69230769 | F63: =IFERROR(AVERAGEIFS(d_Time,d_City,$B63,d_Type,"Delivery",d_Status,"Delivered",d_Year,$P$4,d_City,$Q$4,d_Cuisine,$R$4,d_Pay,$S$4,d_Type,$T$4),0) -> 47.814815 | G63: =IFERROR(AVERAGEIFS(d_Dist,d_City,$B63,d_Type,"Delivery",d_Year,$P$4,d_City,$Q$4,d_Cuisine,$R$4,d_Pay,$S$4,d_Type,$T$4),0) -> 7.9666667 | H63: =SUMIFS(d_Fee,d_City,$B63,d_Type,"Delivery",d_Status,"Delivered",d_Year,$P$4,d_City,$Q$4,d_Cuisine,$R$4,d_Pay,$S$4,d_Type,$T$4) -> 1740
B64: Chennai | C64: =COUNTIFS(d_City,$B64,d_Type,"Delivery",d_Year,$P$4,d_City,$Q$4,d_Cuisine,$R$4,d_Pay,$S$4,d_Type,$T$4) -> 88 | D64: =COUNTIFS(d_City,$B64,d_Type,"Delivery",d_Status,"Delivered",d_Year,$P$4,d_City,$Q$4,d_Cuisine,$R$4,d_Pay,$S$4,d_Type,$T$4) -> 58 | E64: =IFERROR(D64/C64,0) -> 0.65909091 | F64: =IFERROR(AVERAGEIFS(d_Time,d_City,$B64,d_Type,"Delivery",d_Status,"Delivered",d_Year,$P$4,d_City,$Q$4,d_Cuisine,$R$4,d_Pay,$S$4,d_Type,$T$4),0) -> 38.913793 | G64: =IFERROR(AVERAGEIFS(d_Dist,d_City,$B64,d_Type,"Delivery",d_Year,$P$4,d_City,$Q$4,d_Cuisine,$R$4,d_Pay,$S$4,d_Type,$T$4),0) -> 8.275 | H64: =SUMIFS(d_Fee,d_City,$B64,d_Type,"Delivery",d_Status,"Delivered",d_Year,$P$4,d_City,$Q$4,d_Cuisine,$R$4,d_Pay,$S$4,d_Type,$T$4) -> 1950
B65: Noida | C65: =COUNTIFS(d_City,$B65,d_Type,"Delivery",d_Year,$P$4,d_City,$Q$4,d_Cuisine,$R$4,d_Pay,$S$4,d_Type,$T$4) -> 81 | D65: =COUNTIFS(d_City,$B65,d_Type,"Delivery",d_Status,"Delivered",d_Year,$P$4,d_City,$Q$4,d_Cuisine,$R$4,d_Pay,$S$4,d_Type,$T$4) -> 52 | E65: =IFERROR(D65/C65,0) -> 0.64197531 | F65: =IFERROR(AVERAGEIFS(d_Time,d_City,$B65,d_Type,"Delivery",d_Status,"Delivered",d_Year,$P$4,d_City,$Q$4,d_Cuisine,$R$4,d_Pay,$S$4,d_Type,$T$4),0) -> 43.730769 | G65: =IFERROR(AVERAGEIFS(d_Dist,d_City,$B65,d_Type,"Delivery",d_Year,$P$4,d_City,$Q$4,d_Cuisine,$R$4,d_Pay,$S$4,d_Type,$T$4),0) -> 7.5592593 | H65: =SUMIFS(d_Fee,d_City,$B65,d_Type,"Delivery",d_Status,"Delivered",d_Year,$P$4,d_City,$Q$4,d_Cuisine,$R$4,d_Pay,$S$4,d_Type,$T$4) -> 1500
B66: Jaipur | C66: =COUNTIFS(d_City,$B66,d_Type,"Delivery",d_Year,$P$4,d_City,$Q$4,d_Cuisine,$R$4,d_Pay,$S$4,d_Type,$T$4) -> 70 | D66: =COUNTIFS(d_City,$B66,d_Type,"Delivery",d_Status,"Delivered",d_Year,$P$4,d_City,$Q$4,d_Cuisine,$R$4,d_Pay,$S$4,d_Type,$T$4) -> 50 | E66: =IFERROR(D66/C66,0) -> 0.71428571 | F66: =IFERROR(AVERAGEIFS(d_Time,d_City,$B66,d_Type,"Delivery",d_Status,"Delivered",d_Year,$P$4,d_City,$Q$4,d_Cuisine,$R$4,d_Pay,$S$4,d_Type,$T$4),0) -> 40.82 | G66: =IFERROR(AVERAGEIFS(d_Dist,d_City,$B66,d_Type,"Delivery",d_Year,$P$4,d_City,$Q$4,d_Cuisine,$R$4,d_Pay,$S$4,d_Type,$T$4),0) -> 7.5757143 | H66: =SUMIFS(d_Fee,d_City,$B66,d_Type,"Delivery",d_Status,"Delivered",d_Year,$P$4,d_City,$Q$4,d_Cuisine,$R$4,d_Pay,$S$4,d_Type,$T$4) -> 1650
B67: Hyderabad | C67: =COUNTIFS(d_City,$B67,d_Type,"Delivery",d_Year,$P$4,d_City,$Q$4,d_Cuisine,$R$4,d_Pay,$S$4,d_Type,$T$4) -> 72 | D67: =COUNTIFS(d_City,$B67,d_Type,"Delivery",d_Status,"Delivered",d_Year,$P$4,d_City,$Q$4,d_Cuisine,$R$4,d_Pay,$S$4,d_Type,$T$4) -> 43 | E67: =IFERROR(D67/C67,0) -> 0.59722222 | F67: =IFERROR(AVERAGEIFS(d_Time,d_City,$B67,d_Type,"Delivery",d_Status,"Delivered",d_Year,$P$4,d_City,$Q$4,d_Cuisine,$R$4,d_Pay,$S$4,d_Type,$T$4),0) -> 41.744186 | G67: =IFERROR(AVERAGEIFS(d_Dist,d_City,$B67,d_Type,"Delivery",d_Year,$P$4,d_City,$Q$4,d_Cuisine,$R$4,d_Pay,$S$4,d_Type,$T$4),0) -> 6.8152778 | H67: =SUMIFS(d_Fee,d_City,$B67,d_Type,"Delivery",d_Status,"Delivered",d_Year,$P$4,d_City,$Q$4,d_Cuisine,$R$4,d_Pay,$S$4,d_Type,$T$4) -> 1320
B68: Pune | C68: =COUNTIFS(d_City,$B68,d_Type,"Delivery",d_Year,$P$4,d_City,$Q$4,d_Cuisine,$R$4,d_Pay,$S$4,d_Type,$T$4) -> 70 | D68: =COUNTIFS(d_City,$B68,d_Type,"Delivery",d_Status,"Delivered",d_Year,$P$4,d_City,$Q$4,d_Cuisine,$R$4,d_Pay,$S$4,d_Type,$T$4) -> 40 | E68: =IFERROR(D68/C68,0) -> 0.57142857 | F68: =IFERROR(AVERAGEIFS(d_Time,d_City,$B68,d_Type,"Delivery",d_Status,"Delivered",d_Year,$P$4,d_City,$Q$4,d_Cuisine,$R$4,d_Pay,$S$4,d_Type,$T$4),0) -> 40.475 | G68: =IFERROR(AVERAGEIFS(d_Dist,d_City,$B68,d_Type,"Delivery",d_Year,$P$4,d_City,$Q$4,d_Cuisine,$R$4,d_Pay,$S$4,d_Type,$T$4),0) -> 7.6671429 | H68: =SUMIFS(d_Fee,d_City,$B68,d_Type,"Delivery",d_Status,"Delivered",d_Year,$P$4,d_City,$Q$4,d_Cuisine,$R$4,d_Pay,$S$4,d_Type,$T$4) -> 1200
B69: Kolkata | C69: =COUNTIFS(d_City,$B69,d_Type,"Delivery",d_Year,$P$4,d_City,$Q$4,d_Cuisine,$R$4,d_Pay,$S$4,d_Type,$T$4) -> 73 | D69: =COUNTIFS(d_City,$B69,d_Type,"Delivery",d_Status,"Delivered",d_Year,$P$4,d_City,$Q$4,d_Cuisine,$R$4,d_Pay,$S$4,d_Type,$T$4) -> 52 | E69: =IFERROR(D69/C69,0) -> 0.71232877 | F69: =IFERROR(AVERAGEIFS(d_Time,d_City,$B69,d_Type,"Delivery",d_Status,"Delivered",d_Year,$P$4,d_City,$Q$4,d_Cuisine,$R$4,d_Pay,$S$4,d_Type,$T$4),0) -> 40.942308 | G69: =IFERROR(AVERAGEIFS(d_Dist,d_City,$B69,d_Type,"Delivery",d_Year,$P$4,d_City,$Q$4,d_Cuisine,$R$4,d_Pay,$S$4,d_Type,$T$4),0) -> 8.3589041 | H69: =SUMIFS(d_Fee,d_City,$B69,d_Type,"Delivery",d_Status,"Delivered",d_Year,$P$4,d_City,$Q$4,d_Cuisine,$R$4,d_Pay,$S$4,d_Type,$T$4) -> 1770
B70: Lucknow | C70: =COUNTIFS(d_City,$B70,d_Type,"Delivery",d_Year,$P$4,d_City,$Q$4,d_Cuisine,$R$4,d_Pay,$S$4,d_Type,$T$4) -> 64 | D70: =COUNTIFS(d_City,$B70,d_Type,"Delivery",d_Status,"Delivered",d_Year,$P$4,d_City,$Q$4,d_Cuisine,$R$4,d_Pay,$S$4,d_Type,$T$4) -> 44 | E70: =IFERROR(D70/C70,0) -> 0.6875 | F70: =IFERROR(AVERAGEIFS(d_Time,d_City,$B70,d_Type,"Delivery",d_Status,"Delivered",d_Year,$P$4,d_City,$Q$4,d_Cuisine,$R$4,d_Pay,$S$4,d_Type,$T$4),0) -> 40.545455 | G70: =IFERROR(AVERAGEIFS(d_Dist,d_City,$B70,d_Type,"Delivery",d_Year,$P$4,d_City,$Q$4,d_Cuisine,$R$4,d_Pay,$S$4,d_Type,$T$4),0) -> 7.23125 | H70: =SUMIFS(d_Fee,d_City,$B70,d_Type,"Delivery",d_Status,"Delivered",d_Year,$P$4,d_City,$Q$4,d_Cuisine,$R$4,d_Pay,$S$4,d_Type,$T$4) -> 1330
B71: Mumbai | C71: =COUNTIFS(d_City,$B71,d_Type,"Delivery",d_Year,$P$4,d_City,$Q$4,d_Cuisine,$R$4,d_Pay,$S$4,d_Type,$T$4) -> 55 | D71: =COUNTIFS(d_City,$B71,d_Type,"Delivery",d_Status,"Delivered",d_Year,$P$4,d_City,$Q$4,d_Cuisine,$R$4,d_Pay,$S$4,d_Type,$T$4) -> 40 | E71: =IFERROR(D71/C71,0) -> 0.72727273 | F71: =IFERROR(AVERAGEIFS(d_Time,d_City,$B71,d_Type,"Delivery",d_Status,"Delivered",d_Year,$P$4,d_City,$Q$4,d_Cuisine,$R$4,d_Pay,$S$4,d_Type,$T$4),0) -> 39.25 | G71: =IFERROR(AVERAGEIFS(d_Dist,d_City,$B71,d_Type,"Delivery",d_Year,$P$4,d_City,$Q$4,d_Cuisine,$R$4,d_Pay,$S$4,d_Type,$T$4),0) -> 7.7836364 | H71: =SUMIFS(d_Fee,d_City,$B71,d_Type,"Delivery",d_Status,"Delivered",d_Year,$P$4,d_City,$Q$4,d_Cuisine,$R$4,d_Pay,$S$4,d_Type,$T$4) -> 1310
B72: Gurugram | C72: =COUNTIFS(d_City,$B72,d_Type,"Delivery",d_Year,$P$4,d_City,$Q$4,d_Cuisine,$R$4,d_Pay,$S$4,d_Type,$T$4) -> 57 | D72: =COUNTIFS(d_City,$B72,d_Type,"Delivery",d_Status,"Delivered",d_Year,$P$4,d_City,$Q$4,d_Cuisine,$R$4,d_Pay,$S$4,d_Type,$T$4) -> 40 | E72: =IFERROR(D72/C72,0) -> 0.70175439 | F72: =IFERROR(AVERAGEIFS(d_Time,d_City,$B72,d_Type,"Delivery",d_Status,"Delivered",d_Year,$P$4,d_City,$Q$4,d_Cuisine,$R$4,d_Pay,$S$4,d_Type,$T$4),0) -> 43.05 | G72: =IFERROR(AVERAGEIFS(d_Dist,d_City,$B72,d_Type,"Delivery",d_Year,$P$4,d_City,$Q$4,d_Cuisine,$R$4,d_Pay,$S$4,d_Type,$T$4),0) -> 8.0789474 | H72: =SUMIFS(d_Fee,d_City,$B72,d_Type,"Delivery",d_Status,"Delivered",d_Year,$P$4,d_City,$Q$4,d_Cuisine,$R$4,d_Pay,$S$4,d_Type,$T$4) -> 1210
B73: Total / Overall | C73: =SUM(C61:C72) -> 881 | D73: =SUM(D61:D72) -> 592 | E73: =IFERROR(D73/C73,0) -> 0.67196368 | F73: =IFERROR(AVERAGEIFS(d_Time,d_Type,"Delivery",d_Status,"Delivered",d_Year,$P$4,d_City,$Q$4,d_Cuisine,$R$4,d_Pay,$S$4,d_Type,$T$4),0) -> 41.694257 | G73: =IFERROR(AVERAGEIFS(d_Dist,d_Type,"Delivery",d_Year,$P$4,d_City,$Q$4,d_Cuisine,$R$4,d_Pay,$S$4,d_Type,$T$4),0) -> 7.6994325 | H73: =SUM(H61:H72) -> 18100
B74: Avg delivery time and fees are for Delivered orders only; distance is for all delivery orders.
B77: Delivery fleet by distance band
B78: Distance band | C78: Min km (>) | D78: Max km (<=) | E78: Delivery orders | F78: Delivered | G78: Avg delivery time (min) | H78: Avg fee (₹)
B79: 0–3 km | C79: 0 | D79: 3 | E79: =COUNTIFS(d_Dist,">"&$C79,d_Dist,"<="&$D79,d_Type,"Delivery",d_Year,$P$4,d_City,$Q$4,d_Cuisine,$R$4,d_Pay,$S$4,d_Type,$T$4) -> 165 | F79: =COUNTIFS(d_Dist,">"&$C79,d_Dist,"<="&$D79,d_Type,"Delivery",d_Status,"Delivered",d_Year,$P$4,d_City,$Q$4,d_Cuisine,$R$4,d_Pay,$S$4,d_Type,$T$4) -> 112 | G79: =IFERROR(AVERAGEIFS(d_Time,d_Dist,">"&$C79,d_Dist,"<="&$D79,d_Type,"Delivery",d_Status,"Delivered",d_Year,$P$4,d_City,$Q$4,d_Cuisine,$R$4,d_Pay,$S$4,d_Type,$T$4),0) -> 41.116071 | H79: =IFERROR(AVERAGEIFS(d_Fee,d_Dist,">"&$C79,d_Dist,"<="&$D79,d_Type,"Delivery",d_Year,$P$4,d_City,$Q$4,d_Cuisine,$R$4,d_Pay,$S$4,d_Type,$T$4),0) -> 33.212121
B80: 3–6 km | C80: 3 | D80: 6 | E80: =COUNTIFS(d_Dist,">"&$C80,d_Dist,"<="&$D80,d_Type,"Delivery",d_Year,$P$4,d_City,$Q$4,d_Cuisine,$R$4,d_Pay,$S$4,d_Type,$T$4) -> 185 | F80: =COUNTIFS(d_Dist,">"&$C80,d_Dist,"<="&$D80,d_Type,"Delivery",d_Status,"Delivered",d_Year,$P$4,d_City,$Q$4,d_Cuisine,$R$4,d_Pay,$S$4,d_Type,$T$4) -> 121 | G80: =IFERROR(AVERAGEIFS(d_Time,d_Dist,">"&$C80,d_Dist,"<="&$D80,d_Type,"Delivery",d_Status,"Delivered",d_Year,$P$4,d_City,$Q$4,d_Cuisine,$R$4,d_Pay,$S$4,d_Type,$T$4),0) -> 43.355372 | H80: =IFERROR(AVERAGEIFS(d_Fee,d_Dist,">"&$C80,d_Dist,"<="&$D80,d_Type,"Delivery",d_Year,$P$4,d_City,$Q$4,d_Cuisine,$R$4,d_Pay,$S$4,d_Type,$T$4),0) -> 34.054054
B81: 6–9 km | C81: 6 | D81: 9 | E81: =COUNTIFS(d_Dist,">"&$C81,d_Dist,"<="&$D81,d_Type,"Delivery",d_Year,$P$4,d_City,$Q$4,d_Cuisine,$R$4,d_Pay,$S$4,d_Type,$T$4) -> 172 | F81: =COUNTIFS(d_Dist,">"&$C81,d_Dist,"<="&$D81,d_Type,"Delivery",d_Status,"Delivered",d_Year,$P$4,d_City,$Q$4,d_Cuisine,$R$4,d_Pay,$S$4,d_Type,$T$4) -> 123 | G81: =IFERROR(AVERAGEIFS(d_Time,d_Dist,">"&$C81,d_Dist,"<="&$D81,d_Type,"Delivery",d_Status,"Delivered",d_Year,$P$4,d_City,$Q$4,d_Cuisine,$R$4,d_Pay,$S$4,d_Type,$T$4),0) -> 40.837398 | H81: =IFERROR(AVERAGEIFS(d_Fee,d_Dist,">"&$C81,d_Dist,"<="&$D81,d_Type,"Delivery",d_Year,$P$4,d_City,$Q$4,d_Cuisine,$R$4,d_Pay,$S$4,d_Type,$T$4),0) -> 30.05814
B82: 9–12 km | C82: 9 | D82: 12 | E82: =COUNTIFS(d_Dist,">"&$C82,d_Dist,"<="&$D82,d_Type,"Delivery",d_Year,$P$4,d_City,$Q$4,d_Cuisine,$R$4,d_Pay,$S$4,d_Type,$T$4) -> 172 | F82: =COUNTIFS(d_Dist,">"&$C82,d_Dist,"<="&$D82,d_Type,"Delivery",d_Status,"Delivered",d_Year,$P$4,d_City,$Q$4,d_Cuisine,$R$4,d_Pay,$S$4,d_Type,$T$4) -> 115 | G82: =IFERROR(AVERAGEIFS(d_Time,d_Dist,">"&$C82,d_Dist,"<="&$D82,d_Type,"Delivery",d_Status,"Delivered",d_Year,$P$4,d_City,$Q$4,d_Cuisine,$R$4,d_Pay,$S$4,d_Type,$T$4),0) -> 40.469565 | H82: =IFERROR(AVERAGEIFS(d_Fee,d_Dist,">"&$C82,d_Dist,"<="&$D82,d_Type,"Delivery",d_Year,$P$4,d_City,$Q$4,d_Cuisine,$R$4,d_Pay,$S$4,d_Type,$T$4),0) -> 31.802326
B83: 12–15 km | C83: 12 | D83: 15 | E83: =COUNTIFS(d_Dist,">"&$C83,d_Dist,"<="&$D83,d_Type,"Delivery",d_Year,$P$4,d_City,$Q$4,d_Cuisine,$R$4,d_Pay,$S$4,d_Type,$T$4) -> 187 | F83: =COUNTIFS(d_Dist,">"&$C83,d_Dist,"<="&$D83,d_Type,"Delivery",d_Status,"Delivered",d_Year,$P$4,d_City,$Q$4,d_Cuisine,$R$4,d_Pay,$S$4,d_Type,$T$4) -> 121 | G83: =IFERROR(AVERAGEIFS(d_Time,d_Dist,">"&$C83,d_Dist,"<="&$D83,d_Type,"Delivery",d_Status,"Delivered",d_Year,$P$4,d_City,$Q$4,d_Cuisine,$R$4,d_Pay,$S$4,d_Type,$T$4),0) -> 42.603306 | H83: =IFERROR(AVERAGEIFS(d_Fee,d_Dist,">"&$C83,d_Dist,"<="&$D83,d_Type,"Delivery",d_Year,$P$4,d_City,$Q$4,d_Cuisine,$R$4,d_Pay,$S$4,d_Type,$T$4),0) -> 31.497326
B84: Total / Overall | E84: =SUM(E79:E83) -> 881 | F84: =SUM(F79:F83) -> 592
B85: Distance bounds are inputs (blue).
B88: Delivery-order status
B89: Status | C89: Delivery orders | D89: % of delivery orders
B90: Delivered | C90: =COUNTIFS(d_Status,$B90,d_Type,"Delivery",d_Year,$P$4,d_City,$Q$4,d_Cuisine,$R$4,d_Pay,$S$4,d_Type,$T$4) -> 592 | D90: =IFERROR(C90/COUNTIFS(d_Type,"Delivery",d_Year,$P$4,d_City,$Q$4,d_Cuisine,$R$4,d_Pay,$S$4,d_Type,$T$4),0) -> 0.67196368
B91: Pending | C91: =COUNTIFS(d_Status,$B91,d_Type,"Delivery",d_Year,$P$4,d_City,$Q$4,d_Cuisine,$R$4,d_Pay,$S$4,d_Type,$T$4) -> 146 | D91: =IFERROR(C91/COUNTIFS(d_Type,"Delivery",d_Year,$P$4,d_City,$Q$4,d_Cuisine,$R$4,d_Pay,$S$4,d_Type,$T$4),0) -> 0.16572077
B92: Cancelled | C92: =COUNTIFS(d_Status,$B92,d_Type,"Delivery",d_Year,$P$4,d_City,$Q$4,d_Cuisine,$R$4,d_Pay,$S$4,d_Type,$T$4) -> 143 | D92: =IFERROR(C92/COUNTIFS(d_Type,"Delivery",d_Year,$P$4,d_City,$Q$4,d_Cuisine,$R$4,d_Pay,$S$4,d_Type,$T$4),0) -> 0.16231555
B93: Total / Overall | C93: =SUM(C90:C92) -> 881 | D93: =SUM(D90:D92) -> 1
B96: Monthly delivery orders
B97: Month | C97: Month start | D97: Delivery orders | E97: Delivered | F97: Avg delivery time (min)
...

Sheet Delivery Time
B2: Delivery Time Analysis
